Workbook

Sheet LEEME
A1: PLAN FINANCIERO PERSONAL · cómo se usa
A2: Viene con datos ficticios de ejemplo. Para usarlo con los tuyos, sigue docs/GUIA_DESPLIEGUE.md del repositorio.
A4: Cada mes
A5: 1. Descarga | B5: Los movimientos de tus bancos, en el formato que te da cada uno. Ya se reconocen Openbank (cuenta y tarjeta), CaixaBank e ING; otro banco se añade en BANCOS, en el importador.
A6: 2. Déjalos | B6: En la carpeta «Movimientos», junto a este sheet (se crea sola la primera vez que importas).
A7: 3. Importa | B7: Menú Plan financiero → Importar movimientos. No duplica lo que ya estaba, aunque las descargas se solapen.
A8: 4. Revisa | B8: En MOVIMIENTOS, lo amarillo (Bizum, ingresos en efectivo…): elige categoría y explica en Nota.
A10: Qué tocas
A11: MOVIMIENTOS | B11: Solo las columnas Categoría y Nota.
A12: REGLAS | B12: Para que un concepto se categorice solo la próxima vez.
A13: CATEGORÍAS | B13: Qué cuenta como ingreso, gasto o traspaso, y qué es de la casa.
A14: PARÁMETROS | B14: Edad, jubilación, rentabilidades, pensión. Gastos y ahorro salen de tus datos, pero puedes escribir encima.
A15: FLEXIBLE | B15: Si tienes retribución flexible: lo que se descuenta de tu nómina cada mes.
A16: DECISIONES | B16: ¿Y si invierto parte del efectivo, recorto gastos, compro vivienda ahora o dentro de unos años…?
A17: HISTORIAL | B17: Cada vez que cambias una cifra del plan, apunta aquí qué, de qué a qué y por qué.
A18: VIVIENDA · INMUEBLES | B18: Precio, hipoteca y alquiler; y lo que tengas en ladrillo.
A19: VIAJES | B19: Tu cuenta de viajes: lo que aportas al mes, tu parte de cada viaje, si llega, y qué pasa si aportas otra cantidad.
A21: Qué miras
A22: MI FUTURO | B22: El panel: nivel, patrimonio, jubilación, hitos, medallas de ahorro, decisiones y gráficos.
A23: CASA | B23: Gastos de la vivienda por concepto y mes.
A24: MIS DATOS | B24: Saldos de fin de mes e ingresos y gastos, solos.
A25: PANEL_DATOS | B25: Lo que lee el dashboard. No se toca.
A27: Colores | B27: Amarillo con texto azul = lo cambias tú · Verde = viene de otra pestaña o de tus datos · Negro = fórmula.
A28: Ojo | B28: Es una herramienta de planificación, no asesoramiento financiero ni fiscal. Las rentabilidades son supuestos.

Sheet MI FUTURO
A1: MI FUTURO FINANCIERO
A2: ="Datos ficticios de ejemplo a "&TEXT(PROYECCIÓN!$B$4,"mmmm yyyy")&" · estimados: precio de la vivienda y pensión" -> Datos ficticios de ejemplo a September 2026 · estimados: precio de la vivienda y pensión
A4: TU NIVEL | C4: PATRIMONIO LÍQUIDO HOY | E4: LIBERTAD FINANCIERA HOY | H4: ="CUENTA DE VIAJES · FIN DE "&VIAJES!$B$7 -> CUENTA DE VIAJES · FIN DE 2026
A5: =INDEX(PARÁMETROS!$B$25:$B$31,MATCH(PROYECCIÓN!$M$15,PARÁMETROS!$A$25:$A$31,1)) -> 🛡️ Escudo | C5: =PROYECCIÓN!$B$8 -> 67957.06 | E5: =PROYECCIÓN!$M$15 -> 0.13724131 | H5: =VIAJES!$B$10 -> 1900
A6: =IFERROR(REPT("█",ROUND((PROYECCIÓN!$M$15-INDEX(PARÁMETROS!$A$25:$A$31,MATCH(PROYECCIÓN!$M$15,PARÁMETROS!$A$25:$A$31,1)))/(INDEX(PARÁMETROS!$A$25:$A$31,MATCH(PROYECCIÓN!$M$15,PARÁMETROS!$A$25:$A$31,1)+1)-INDEX(PARÁMETROS!$A$25:$A$31,MATCH(PROYECCIÓN!$M$15,PARÁMETROS!$A$25:$A$31,1)))*10,0))&REPT("░",10-ROUND((PROYECCIÓN!$M$15-INDEX(PARÁMETROS!$A$25:$A$31,MATCH(PROYECCIÓN!$M$15,PARÁMETROS!$A$25:$A$31,1)))/(INDEX(PARÁMETROS!$A$25:$A$31,MATCH(PROYECCIÓN!$M$15,PARÁMETROS!$A$25:$A$31,1)+1)-INDEX(PARÁMETROS!$A$25:$A$31,MATCH(PROYECCIÓN!$M$15,PARÁMETROS!$A$25:$A$31,1)))*10,0)),"██████████") -> █████████░ | C6: ="Con tus inmuebles: "&TEXT(PROYECCIÓN!$B$10,"#,##0")&" €" -> Con tus inmuebles: 67,957 € | E6: =REPT("█",ROUND(MIN(1,PROYECCIÓN!$M$15)*20,0))&REPT("░",20-ROUND(MIN(1,PROYECCIÓN!$M$15)*20,0)) -> ███░░░░░░░░░░░░░░░░░ | H6: ="Aportas "&TEXT(VIAJES!$B$4,"#,##0")&" €/mes · "&VIAJES!$B$11&" viajes en "&VIAJES!$B$7 -> Aportas 150 €/mes · 2 viajes en 2026
A7: =IFERROR("Siguiente: "&INDEX(PARÁMETROS!$B$25:$B$31,MATCH(PROYECCIÓN!$M$15,PARÁMETROS!$A$25:$A$31,1)+1)&" al "&TEXT(INDEX(PARÁMETROS!$A$25:$A$31,MATCH(PROYECCIÓN!$M$15,PARÁMETROS!$A$25:$A$31,1)+1),"0%"),"Nivel máximo") -> Siguiente: 🧭 Brújula al 15% | C7: ="CaixaBank "&TEXT(INDEX('MIS DATOS'!$B$6:$B$245,COUNT('MIS DATOS'!$A$6:$A$245)),"#,##0")&" · Openbank "&TEXT(INDEX('MIS DATOS'!$C$6:$C$245,COUNT('MIS DATOS'!$A$6:$A$245)),"#,##0")&" · ING "&TEXT(INDEX('MIS DATOS'!$D$6:$D$245,COUNT('MIS DATOS'!$A$6:$A$245)),"#,##0") -> CaixaBank 10,501 · Openbank 1,450 · ING 56,006 | E7: ="Tu dinero cubre el "&TEXT(PROYECCIÓN!$M$15,"0%")&" de tus gastos (regla del "&TEXT(PARÁMETROS!$B$16,"0%")&")" -> Tu dinero cubre el 14% de tus gastos (regla del 4%) | H7: =VIAJES!$B$12 -> ✅ Llega para todos los viajes apuntados
A8: ="🏠 Casa: "&TEXT(CASA!$O$13,"#,##0")&" €/mes de media · 🧾 Por revisar: "&COUNTIFS(MOVIMIENTOS!$H$4:$H$20000,"Por revisar",MOVIMIENTOS!$B$4:$B$20000,">="&'MIS DATOS'!$A$6)&" movimientos desde "&TEXT('MIS DATOS'!$A$6,"mmmm yyyy")&" (cuentan cuando les pongas categoría)" -> 🏠 Casa: 969 €/mes de media · 🧾 Por revisar: 2 movimientos desde October 2025 (cuentan cuando les pongas categoría)
A9: ="¿CUÁNTO TENDRÁS A LOS "&PARÁMETROS!$B$5&"?" -> ¿CUÁNTO TENDRÁS A LOS 67?
A10: PATRIMONIO LÍQUIDO | C10: LO QUE PONES DE TU BOLSILLO | E10: LO QUE GENERAN TUS INVERSIONES | G10: EN € DE HOY | I10: INGRESO MENSUAL (€ DE HOY)
A11: =INDEX(PROYECCIÓN!$G$15:$G$45,PROYECCIÓN!$B$11+1) -> 502169.25 | C11: =INDEX(PROYECCIÓN!$I$15:$I$45,PROYECCIÓN!$B$11+1)+INDEX(PROYECCIÓN!$J$15:$J$45,PROYECCIÓN!$B$11+1) -> 462658.19 | E11: =INDEX(PROYECCIÓN!$K$15:$K$45,PROYECCIÓN!$B$11+1) -> 39511.054 | G11: =INDEX(PROYECCIÓN!$H$15:$H$45,PROYECCIÓN!$B$11+1) -> 264258.89 | I11: =INDEX(PROYECCIÓN!$H$15:$H$45,PROYECCIÓN!$B$11+1)*PARÁMETROS!$B$16/12+PARÁMETROS!$B$17*14/12 -> 2339.1963
A12: ="Por cada euro que pones, tus inversiones añaden "&TEXT(E11/C11,"0.00")&" €. El ingreso mensual suma la regla del "&TEXT(PARÁMETROS!$B$16,"0%")&" y una pensión pública de "&TEXT(PARÁMETROS!$B$17,"#,##0")&" € × 14 pagas (de hoy), repartida en 12 meses." -> Por cada euro que pones, tus inversiones añaden 0.09 €. El ingreso mensual suma la regla del 4% y una pensión pública de 1,250 € × 14 pagas (de hoy), repartida en 12 meses.
A14: 🏖️ TU JUBILACIÓN · ¿hasta cuándo te dura el dinero?
A15: SIN DECISIONES | C15: CON TUS DECISIONES | E15: LO QUE SACAS EL 1.er AÑO | G15: PENSIÓN + RENTAS EL 1.er AÑO
A16: =IF(PROYECCIÓN!$B$92>=PARÁMETROS!$B$5+40,"Más allá de los "&(PARÁMETROS!$B$5+40),"Hasta los "&PROYECCIÓN!$B$92) -> Más allá de los 107 | C16: =IF(PROYECCIÓN!$B$93>=PARÁMETROS!$B$5+40,"Más allá de los "&(PARÁMETROS!$B$5+40),"Hasta los "&PROYECCIÓN!$B$93) -> Más allá de los 107 | E16: =PROYECCIÓN!$H$50 -> 4383.1961 | G16: =PROYECCIÓN!$F$50+PROYECCIÓN!$G$50 -> 33255.122
A17: ="Cada año sacas lo que no cubren la pensión y las rentas; el capital renta un "&TEXT(PARÁMETROS!$B$20,"0%")&" y la pensión sube con la inflación. Con decisiones incluye la cuota si la hipoteca sigue viva." -> Cada año sacas lo que no cubren la pensión y las rentas; el capital renta un 3% y la pensión sube con la inflación. Con decisiones incluye la cuota si la hipoteca sigue viva.
A19: 🏆 TUS HITOS · se desbloquean solos según tu plan
A20: Hito | B20: Meta | C20: Hoy | D20: % | E20: Año | F20: Edad | G20: Faltan (años) | H20: Estado | I20: Progreso
A21: 🛟 Colchón de emergencia | B21: =PARÁMETROS!$B$15*PARÁMETROS!$B$18 -> 9903.295 | C21: =PROYECCIÓN!$B$5 -> 67957.06 | D21: =MIN(1,IFERROR(C21/B21,0)) -> 1 | E21: =IF(C21>=B21,"Hoy",IF(COUNTIF(PROYECCIÓN!$D$15:$D$45,"<"&B21)>PROYECCIÓN!$B$11,"—",INDEX(PROYECCIÓN!$C$15:$C$45,COUNTIF(PROYECCIÓN!$D$15:$D$45,"<"&B21)+1))) -> Hoy | F21: =IF(OR(C21>=B21,COUNTIF(PROYECCIÓN!$D$15:$D$45,"<"&B21)>PROYECCIÓN!$B$11),"",INDEX(PROYECCIÓN!$B$15:$B$45,COUNTIF(PROYECCIÓN!$D$15:$D$45,"<"&B21)+1)) | G21: =IF(OR(C21>=B21,COUNTIF(PROYECCIÓN!$D$15:$D$45,"<"&B21)>PROYECCIÓN!$B$11),"",COUNTIF(PROYECCIÓN!$D$15:$D$45,"<"&B21)) | H21: =IF(C21>=B21,"✅ Conseguido",IF(COUNTIF(PROYECCIÓN!$D$15:$D$45,"<"&B21)>PROYECCIÓN!$B$11,"⛔ Antes de jubilarte no","🔄 En camino")) -> ✅ Conseguido | I21: =REPT("█",ROUND(D21*10,0))&REPT("░",10-ROUND(D21*10,0))&" "&TEXT(D21,"0%") -> ██████████ 100%
A22: 💶 100.000 € de patrimonio líquido | B22: 100000 | C22: =PROYECCIÓN!$B$8 -> 67957.06 | D22: =MIN(1,IFERROR(C22/B22,0)) -> 0.6795706 | E22: =IF(C22>=B22,"Hoy",IF(COUNTIF(PROYECCIÓN!$G$15:$G$45,"<"&B22)>PROYECCIÓN!$B$11,"—",INDEX(PROYECCIÓN!$C$15:$C$45,COUNTIF(PROYECCIÓN!$G$15:$G$45,"<"&B22)+1))) -> 2029 | F22: =IF(OR(C22>=B22,COUNTIF(PROYECCIÓN!$G$15:$G$45,"<"&B22)>PROYECCIÓN!$B$11),"",INDEX(PROYECCIÓN!$B$15:$B$45,COUNTIF(PROYECCIÓN!$G$15:$G$45,"<"&B22)+1)) -> 44 | G22: =IF(OR(C22>=B22,COUNTIF(PROYECCIÓN!$G$15:$G$45,"<"&B22)>PROYECCIÓN!$B$11),"",COUNTIF(PROYECCIÓN!$G$15:$G$45,"<"&B22)) -> 3 | H22: =IF(C22>=B22,"✅ Conseguido",IF(COUNTIF(PROYECCIÓN!$G$15:$G$45,"<"&B22)>PROYECCIÓN!$B$11,"⛔ Antes de jubilarte no","🔄 En camino")) -> 🔄 En camino | I22: =REPT("█",ROUND(D22*10,0))&REPT("░",10-ROUND(D22*10,0))&" "&TEXT(D22,"0%") -> ███████░░░ 68%
A23: 💰 150.000 € de patrimonio líquido | B23: 150000 | C23: =PROYECCIÓN!$B$8 -> 67957.06 | D23: =MIN(1,IFERROR(C23/B23,0)) -> 0.45304707 | E23: =IF(C23>=B23,"Hoy",IF(COUNTIF(PROYECCIÓN!$G$15:$G$45,"<"&B23)>PROYECCIÓN!$B$11,"—",INDEX(PROYECCIÓN!$C$15:$C$45,COUNTIF(PROYECCIÓN!$G$15:$G$45,"<"&B23)+1))) -> 2033 | F23: =IF(OR(C23>=B23,COUNTIF(PROYECCIÓN!$G$15:$G$45,"<"&B23)>PROYECCIÓN!$B$11),"",INDEX(PROYECCIÓN!$B$15:$B$45,COUNTIF(PROYECCIÓN!$G$15:$G$45,"<"&B23)+1)) -> 48 | G23: =IF(OR(C23>=B23,COUNTIF(PROYECCIÓN!$G$15:$G$45,"<"&B23)>PROYECCIÓN!$B$11),"",COUNTIF(PROYECCIÓN!$G$15:$G$45,"<"&B23)) -> 7 | H23: =IF(C23>=B23,"✅ Conseguido",IF(COUNTIF(PROYECCIÓN!$G$15:$G$45,"<"&B23)>PROYECCIÓN!$B$11,"⛔ Antes de jubilarte no","🔄 En camino")) -> 🔄 En camino | I23: =REPT("█",ROUND(D23*10,0))&REPT("░",10-ROUND(D23*10,0))&" "&TEXT(D23,"0%") -> █████░░░░░ 45%
A24: 🏠 Vivienda comprada | B24: 1 | C24: =VIVIENDA!$B$6 -> 0 | D24: =MIN(1,IFERROR(C24/B24,0)) -> 0 | E24: =IF(C24>=B24,"Hoy",IF(DECISIONES!$B$10="Sí",PARÁMETROS!$B$6+DECISIONES!$B$14,"—")) -> 2026 | F24: =IF(C24>=B24,"",IF(DECISIONES!$B$10="Sí",PARÁMETROS!$B$4+DECISIONES!$B$14,"")) -> 41 | G24: =IF(C24>=B24,"",IF(DECISIONES!$B$10="Sí",DECISIONES!$B$14,"")) -> 0 | H24: =IF(C24>=B24,"✅ Conseguido",IF(DECISIONES!$B$10="Sí","📅 En DECISIONES","🤔 Por decidir")) -> 📅 En DECISIONES | I24: =REPT("█",ROUND(D24*10,0))&REPT("░",10-ROUND(D24*10,0))&" "&TEXT(D24,"0%") -> ░░░░░░░░░░ 0%
A25: 🔓 Libertad financiera 25 % | B25: 0.25 | C25: =PROYECCIÓN!$M$15 -> 0.13724131 | D25: =MIN(1,IFERROR(C25/B25,0)) -> 0.54896525 | E25: =IF(C25>=B25,"Hoy",IF(COUNTIF(PROYECCIÓN!$M$15:$M$45,"<"&B25)>PROYECCIÓN!$B$11,"—",INDEX(PROYECCIÓN!$C$15:$C$45,COUNTIF(PROYECCIÓN!$M$15:$M$45,"<"&B25)+1))) -> 2032 | F25: =IF(OR(C25>=B25,COUNTIF(PROYECCIÓN!$M$15:$M$45,"<"&B25)>PROYECCIÓN!$B$11),"",INDEX(PROYECCIÓN!$B$15:$B$45,COUNTIF(PROYECCIÓN!$M$15:$M$45,"<"&B25)+1)) -> 47 | G25: =IF(OR(C25>=B25,COUNTIF(PROYECCIÓN!$M$15:$M$45,"<"&B25)>PROYECCIÓN!$B$11),"",COUNTIF(PROYECCIÓN!$M$15:$M$45,"<"&B25)) -> 6 | H25: =IF(C25>=B25,"✅ Conseguido",IF(COUNTIF(PROYECCIÓN!$M$15:$M$45,"<"&B25)>PROYECCIÓN!$B$11,"⛔ Antes de jubilarte no","🔄 En camino")) -> 🔄 En camino | I25: =REPT("█",ROUND(D25*10,0))&REPT("░",10-ROUND(D25*10,0))&" "&TEXT(D25,"0%") -> █████░░░░░ 55%
A26: 💎 200.000 € de patrimonio líquido | B26: 200000 | C26: =PROYECCIÓN!$B$8 -> 67957.06 | D26: =MIN(1,IFERROR(C26/B26,0)) -> 0.3397853 | E26: =IF(C26>=B26,"Hoy",IF(COUNTIF(PROYECCIÓN!$G$15:$G$45,"<"&B26)>PROYECCIÓN!$B$11,"—",INDEX(PROYECCIÓN!$C$15:$C$45,COUNTIF(PROYECCIÓN!$G$15:$G$45,"<"&B26)+1))) -> 2036 | F26: =IF(OR(C26>=B26,COUNTIF(PROYECCIÓN!$G$15:$G$45,"<"&B26)>PROYECCIÓN!$B$11),"",INDEX(PROYECCIÓN!$B$15:$B$45,COUNTIF(PROYECCIÓN!$G$15:$G$45,"<"&B26)+1)) -> 51 | G26: =IF(OR(C26>=B26,COUNTIF(PROYECCIÓN!$G$15:$G$45,"<"&B26)>PROYECCIÓN!$B$11),"",COUNTIF(PROYECCIÓN!$G$15:$G$45,"<"&B26)) -> 10 | H26: =IF(C26>=B26,"✅ Conseguido",IF(COUNTIF(PROYECCIÓN!$G$15:$G$45,"<"&B26)>PROYECCIÓN!$B$11,"⛔ Antes de jubilarte no","🔄 En camino")) -> 🔄 En camino | I26: =REPT("█",ROUND(D26*10,0))&REPT("░",10-ROUND(D26*10,0))&" "&TEXT(D26,"0%") -> ███░░░░░░░ 34%
A27: 🔓 Libertad financiera 50 % | B27: 0.5 | C27: =PROYECCIÓN!$M$15 -> 0.13724131 | D27: =MIN(1,IFERROR(C27/B27,0)) -> 0.27448262 | E27: =IF(C27>=B27,"Hoy",IF(COUNTIF(PROYECCIÓN!$M$15:$M$45,"<"&B27)>PROYECCIÓN!$B$11,"—",INDEX(PROYECCIÓN!$C$15:$C$45,COUNTIF(PROYECCIÓN!$M$15:$M$45,"<"&B27)+1))) -> 2049 | F27: =IF(OR(C27>=B27,COUNTIF(PROYECCIÓN!$M$15:$M$45,"<"&B27)>PROYECCIÓN!$B$11),"",INDEX(PROYECCIÓN!$B$15:$B$45,COUNTIF(PROYECCIÓN!$M$15:$M$45,"<"&B27)+1)) -> 64 | G27: =IF(OR(C27>=B27,COUNTIF(PROYECCIÓN!$M$15:$M$45,"<"&B27)>PROYECCIÓN!$B$11),"",COUNTIF(PROYECCIÓN!$M$15:$M$45,"<"&B27)) -> 23 | H27: =IF(C27>=B27,"✅ Conseguido",IF(COUNTIF(PROYECCIÓN!$M$15:$M$45,"<"&B27)>PROYECCIÓN!$B$11,"⛔ Antes de jubilarte no","🔄 En camino")) -> 🔄 En camino | I27: =REPT("█",ROUND(D27*10,0))&REPT("░",10-ROUND(D27*10,0))&" "&TEXT(D27,"0%") -> ███░░░░░░░ 27%
A28: 🏖️ Que el dinero te dure hasta los 90 | B28: 90 | C28: =PROYECCIÓN!$B$92 -> 108 | D28: =MIN(1,IFERROR(C28/B28,0)) -> 1 | E28: ="" | F28: ="" | G28: ="" | H28: =IF(C28>=B28,"✅ Cubierto","⚠️ Ajusta el plan") -> ✅ Cubierto | I28: =REPT("█",ROUND(D28*10,0))&REPT("░",10-ROUND(D28*10,0))&" "&TEXT(D28,"0%") -> ██████████ 100%
A30: 🏅 TUS LOGROS DE AHORRO · medalla por % de ingresos ahorrado
A31: Año | B31: Ingresos | C31: Gastos | D31: Ahorro | E31: % ahorrado | F31: Medalla | G31: Meses con datos
A32: =PARÁMETROS!$B$6-1+0 -> 2025 | B32: =SUMIFS('MIS DATOS'!$G$6:$G$245,'MIS DATOS'!$L$6:$L$245,A32) -> 8698.69 | C32: =SUMIFS('MIS DATOS'!$H$6:$H$245,'MIS DATOS'!$L$6:$L$245,A32) -> 4904.55 | D32: =B32-C32 -> 3794.14 | E32: =IF(G32=0,"",D32/B32) -> 0.43617372 | F32: =IF(G32=0,"",IF(E32>=0.4,"🥇 Oro",IF(E32>=0.25,"🥈 Plata",IF(E32>=0.1,"🥉 Bronce","—")))&IF(G32<12," (parcial)","")) -> 🥇 Oro (parcial) | G32: =COUNTIF('MIS DATOS'!$L$6:$L$245,A32) -> 3
A33: =PARÁMETROS!$B$6-1+1 -> 2026 | B33: =SUMIFS('MIS DATOS'!$G$6:$G$245,'MIS DATOS'!$L$6:$L$245,A33) -> 22830.22 | C33: =SUMIFS('MIS DATOS'!$H$6:$H$245,'MIS DATOS'!$L$6:$L$245,A33) -> 14902.04 | D33: =B33-C33 -> 7928.18 | E33: =IF(G33=0,"",D33/B33) -> 0.34726691 | F33: =IF(G33=0,"",IF(E33>=0.4,"🥇 Oro",IF(E33>=0.25,"🥈 Plata",IF(E33>=0.1,"🥉 Bronce","—")))&IF(G33<12," (parcial)","")) -> 🥈 Plata (parcial) | G33: =COUNTIF('MIS DATOS'!$L$6:$L$245,A33) -> 9
A34: =PARÁMETROS!$B$6-1+2 -> 2027 | B34: =SUMIFS('MIS DATOS'!$G$6:$G$245,'MIS DATOS'!$L$6:$L$245,A34) -> 0 | C34: =SUMIFS('MIS DATOS'!$H$6:$H$245,'MIS DATOS'!$L$6:$L$245,A34) -> 0 | D34: =B34-C34 -> 0 | E34: =IF(G34=0,"",D34/B34) | F34: =IF(G34=0,"",IF(E34>=0.4,"🥇 Oro",IF(E34>=0.25,"🥈 Plata",IF(E34>=0.1,"🥉 Bronce","—")))&IF(G34<12," (parcial)","")) | G34: =COUNTIF('MIS DATOS'!$L$6:$L$245,A34) -> 0
A35: =PARÁMETROS!$B$6-1+3 -> 2028 | B35: =SUMIFS('MIS DATOS'!$G$6:$G$245,'MIS DATOS'!$L$6:$L$245,A35) -> 0 | C35: =SUMIFS('MIS DATOS'!$H$6:$H$245,'MIS DATOS'!$L$6:$L$245,A35) -> 0 | D35: =B35-C35 -> 0 | E35: =IF(G35=0,"",D35/B35) | F35: =IF(G35=0,"",IF(E35>=0.4,"🥇 Oro",IF(E35>=0.25,"🥈 Plata",IF(E35>=0.1,"🥉 Bronce","—")))&IF(G35<12," (parcial)","")) | G35: =COUNTIF('MIS DATOS'!$L$6:$L$245,A35) -> 0
A36: Oro ≥ 40 % · Plata ≥ 25 % · Bronce ≥ 10 %
A38: 🧭 TUS DECISIONES · ¿qué pasa si…?
B39: SIN DECISIONES | D39: CON TUS DECISIONES | G39: DIFERENCIA
A40: ="Patrimonio líquido a los "&PARÁMETROS!$B$5 -> Patrimonio líquido a los 67 | B40: =INDEX(PROYECCIÓN!$G$15:$G$45,PROYECCIÓN!$B$11+1) -> 502169.25 | D40: =INDEX(PROYECCIÓN!$O$15:$O$45,PROYECCIÓN!$B$11+1) -> 488086.56 | G40: =D40-B40 -> -14082.689
A41: Con tus inmuebles (netos de hipoteca) | B41: =INDEX(PROYECCIÓN!$T$15:$T$45,PROYECCIÓN!$B$11+1) -> 502169.25 | D41: =INDEX(PROYECCIÓN!$U$15:$U$45,PROYECCIÓN!$B$11+1) -> 962536.63 | G41: =D41-B41 -> 460367.39
A42: Libertad financiera | B42: =INDEX(PROYECCIÓN!$M$15:$M$45,PROYECCIÓN!$B$11+1) -> 0.53367873 | D42: =INDEX(PROYECCIÓN!$Q$15:$Q$45,PROYECCIÓN!$B$11+1) -> 1.0694662
A43: ="Decisiones: "&TEXT(DECISIONES!$B$5,"#,##0")&" € del efectivo a inversión, +"&TEXT(DECISIONES!$B$6,"#,##0")&" €/mes a inversión, −"&TEXT(DECISIONES!$B$7,"#,##0")&" €/mes de gastos"&IF(DECISIONES!$B$10="Sí",", compra de la vivienda ("&DECISIONES!$B$11&")","")&". Comprar pasa dinero líquido a ladrillo: mira las dos filas." -> Decisiones: 0 € del efectivo a inversión, +0 €/mes a inversión, −0 €/mes de gastos, compra de la vivienda (Comprar ya). Comprar pasa dinero líquido a ladrillo: mira las dos filas.
A45: 📊 TU FUTURO EN GRÁFICOS

Sheet MIS DATOS
A1: MIS DATOS
A2: Se rellena sola: saldos a fin de mes que trae el importador (B–D) e ingresos y gastos de MOVIMIENTOS. Inversión y plan de pensiones (E–F), a mano si algún día los tienes.
A3: La primera fila es el primer mes del que hay datos de las tres cuentas. Si descargas más histórico de todas, empieza antes.
A5: Mes | B5: CaixaBank | C5: Openbank | D5: ING | E5: Inversión | F5: Plan de pensiones | G5: Ingresos del mes | H5: Gastos del mes | I5: Ahorro del mes | J5: % de ahorro | K5: Patrimonio líquido | L5: Año | M5: Por revisar | N5: Mes completo
A6: 45931 | B6: 3446.26 | C6: 1080 | D6: 52332.69 | E6: 0 | F6: 0 | G6: =IF(A6="","",SUMIFS(MOVIMIENTOS!$E$4:$E$20000,MOVIMIENTOS!$B$4:$B$20000,A6,MOVIMIENTOS!$H$4:$H$20000,"Ingreso")+SUMIFS(FLEXIBLE!$D$4:$D$200,FLEXIBLE!$F$4:$F$200,A6)) -> 2182.69 | H6: =IF(A6="","",-SUMIFS(MOVIMIENTOS!$E$4:$E$20000,MOVIMIENTOS!$B$4:$B$20000,A6,MOVIMIENTOS!$H$4:$H$20000,"Gasto")+SUMIFS(FLEXIBLE!$D$4:$D$200,FLEXIBLE!$F$4:$F$200,A6)) -> 1569.48 | I6: =IF(A6="","",G6-H6) -> 613.21 | J6: =IF(A6="","",IF(N6=0,"en curso",IF(N(G6)=0,"",I6/G6))) -> 0.28094232 | K6: =IF(A6="","",SUM(B6:F6)) -> 56858.95 | L6: =IF(A6="","",YEAR(A6)) -> 2025 | M6: =IF(A6="","",COUNTIFS(MOVIMIENTOS!$B$4:$B$20000,A6,MOVIMIENTOS!$H$4:$H$20000,"Por revisar")) -> 0 | N6: =IF(A6="","",IF(A6<DATE(YEAR(TODAY()),MONTH(TODAY()),1),1,0)) -> 1
A7: 45962 | B7: 3570.92 | C7: 1114.26 | D7: 52665.59 | E7: 0 | F7: 0 | G7: =IF(A7="","",SUMIFS(MOVIMIENTOS!$E$4:$E$20000,MOVIMIENTOS!$B$4:$B$20000,A7,MOVIMIENTOS!$H$4:$H$20000,"Ingreso")+SUMIFS(FLEXIBLE!$D$4:$D$200,FLEXIBLE!$F$4:$F$200,A7)) -> 2182.9 | H7: =IF(A7="","",-SUMIFS(MOVIMIENTOS!$E$4:$E$20000,MOVIMIENTOS!$B$4:$B$20000,A7,MOVIMIENTOS!$H$4:$H$20000,"Gasto")+SUMIFS(FLEXIBLE!$D$4:$D$200,FLEXIBLE!$F$4:$F$200,A7)) -> 1735.4 | I7: =IF(A7="","",G7-H7) -> 447.5 | J7: =IF(A7="","",IF(N7=0,"en curso",IF(N(G7)=0,"",I7/G7))) -> 0.20500252 | K7: =IF(A7="","",SUM(B7:F7)) -> 57350.77 | L7: =IF(A7="","",YEAR(A7)) -> 2025 | M7: =IF(A7="","",COUNTIFS(MOVIMIENTOS!$B$4:$B$20000,A7,MOVIMIENTOS!$H$4:$H$20000,"Por revisar")) -> 0 | N7: =IF(A7="","",IF(A7<DATE(YEAR(TODAY()),MONTH(TODAY()),1),1,0)) -> 1
A8: 45992 | B8: 5931.77 | C8: 1104.2 | D8: 52998.69 | E8: 0 | F8: 0 | G8: =IF(A8="","",SUMIFS(MOVIMIENTOS!$E$4:$E$20000,MOVIMIENTOS!$B$4:$B$20000,A8,MOVIMIENTOS!$H$4:$H$20000,"Ingreso")+SUMIFS(FLEXIBLE!$D$4:$D$200,FLEXIBLE!$F$4:$F$200,A8)) -> 4333.1 | H8: =IF(A8="","",-SUMIFS(MOVIMIENTOS!$E$4:$E$20000,MOVIMIENTOS!$B$4:$B$20000,A8,MOVIMIENTOS!$H$4:$H$20000,"Gasto")+SUMIFS(FLEXIBLE!$D$4:$D$200,FLEXIBLE!$F$4:$F$200,A8)) -> 1599.67 | I8: =IF(A8="","",G8-H8) -> 2733.43 | J8: =IF(A8="","",IF(N8=0,"en curso",IF(N(G8)=0,"",I8/G8))) -> 0.63082551 | K8: =IF(A8="","",SUM(B8:F8)) -> 60034.66 | L8: =IF(A8="","",YEAR(A8)) -> 2025 | M8: =IF(A8="","",COUNTIFS(MOVIMIENTOS!$B$4:$B$20000,A8,MOVIMIENTOS!$H$4:$H$20000,"Por revisar")) -> 0 | N8: =IF(A8="","",IF(A8<DATE(YEAR(TODAY()),MONTH(TODAY()),1),1,0)) -> 1
A9: 46023 | B9: 6101.39 | C9: 1143.68 | D9: 53332 | E9: 0 | F9: 0 | G9: =IF(A9="","",SUMIFS(MOVIMIENTOS!$E$4:$E$20000,MOVIMIENTOS!$B$4:$B$20000,A9,MOVIMIENTOS!$H$4:$H$20000,"Ingreso")+SUMIFS(FLEXIBLE!$D$4:$D$200,FLEXIBLE!$F$4:$F$200,A9)) -> 2183.31 | H9: =IF(A9="","",-SUMIFS(MOVIMIENTOS!$E$4:$E$20000,MOVIMIENTOS!$B$4:$B$20000,A9,MOVIMIENTOS!$H$4:$H$20000,"Gasto")+SUMIFS(FLEXIBLE!$D$4:$D$200,FLEXIBLE!$F$4:$F$200,A9)) -> 1714.98 | I9: =IF(A9="","",G9-H9) -> 468.33 | J9: =IF(A9="","",IF(N9=0,"en curso",IF(N(G9)=0,"",I9/G9))) -> 0.21450458 | K9: =IF(A9="","",SUM(B9:F9)) -> 60577.07 | L9: =IF(A9="","",YEAR(A9)) -> 2026 | M9: =IF(A9="","",COUNTIFS(MOVIMIENTOS!$B$4:$B$20000,A9,MOVIMIENTOS!$H$4:$H$20000,"Por revisar")) -> 0 | N9: =IF(A9="","",IF(A9<DATE(YEAR(TODAY()),MONTH(TODAY()),1),1,0)) -> 1
A10: 46054 | B10: 6319.16 | C10: 1109.08 | D10: 53665.52 | E10: 0 | F10: 0 | G10: =IF(A10="","",SUMIFS(MOVIMIENTOS!$E$4:$E$20000,MOVIMIENTOS!$B$4:$B$20000,A10,MOVIMIENTOS!$H$4:$H$20000,"Ingreso")+SUMIFS(FLEXIBLE!$D$4:$D$200,FLEXIBLE!$F$4:$F$200,A10)) -> 2183.52 | H10: =IF(A10="","",-SUMIFS(MOVIMIENTOS!$E$4:$E$20000,MOVIMIENTOS!$B$4:$B$20000,A10,MOVIMIENTOS!$H$4:$H$20000,"Gasto")+SUMIFS(FLEXIBLE!$D$4:$D$200,FLEXIBLE!$F$4:$F$200,A10)) -> 1587.05 | I10: =IF(A10="","",G10-H10) -> 596.47 | J10: =IF(A10="","",IF(N10=0,"en curso",IF(N(G10)=0,"",I10/G10))) -> 0.27316901 | K10: =IF(A10="","",SUM(B10:F10)) -> 61093.76 | L10: =IF(A10="","",YEAR(A10)) -> 2026 | M10: =IF(A10="","",COUNTIFS(MOVIMIENTOS!$B$4:$B$20000,A10,MOVIMIENTOS!$H$4:$H$20000,"Por revisar")) -> 0 | N10: =IF(A10="","",IF(A10<DATE(YEAR(TODAY()),MONTH(TODAY()),1),1,0)) -> 1
A11: 46082 | B11: 6481.69 | C11: 1154.26 | D11: 53999.25 | E11: 0 | F11: 0 | G11: =IF(A11="","",SUMIFS(MOVIMIENTOS!$E$4:$E$20000,MOVIMIENTOS!$B$4:$B$20000,A11,MOVIMIENTOS!$H$4:$H$20000,"Ingreso")+SUMIFS(FLEXIBLE!$D$4:$D$200,FLEXIBLE!$F$4:$F$200,A11)) -> 2183.73 | H11: =IF(A11="","",-SUMIFS(MOVIMIENTOS!$E$4:$E$20000,MOVIMIENTOS!$B$4:$B$20000,A11,MOVIMIENTOS!$H$4:$H$20000,"Gasto")+SUMIFS(FLEXIBLE!$D$4:$D$200,FLEXIBLE!$F$4:$F$200,A11)) -> 1605.51 | I11: =IF(A11="","",G11-H11) -> 578.22 | J11: =IF(A11="","",IF(N11=0,"en curso",IF(N(G11)=0,"",I11/G11))) -> 0.26478548 | K11: =IF(A11="","",SUM(B11:F11)) -> 61635.2 | L11: =IF(A11="","",YEAR(A11)) -> 2026 | M11: =IF(A11="","",COUNTIFS(MOVIMIENTOS!$B$4:$B$20000,A11,MOVIMIENTOS!$H$4:$H$20000,"Por revisar")) -> 0 | N11: =IF(A11="","",IF(A11<DATE(YEAR(TODAY()),MONTH(TODAY()),1),1,0)) -> 1
A12: 46113 | B12: 6640.62 | C12: 1236.22 | D12: 54333.19 | E12: 0 | F12: 0 | G12: =IF(A12="","",SUMIFS(MOVIMIENTOS!$E$4:$E$20000,MOVIMIENTOS!$B$4:$B$20000,A12,MOVIMIENTOS!$H$4:$H$20000,"Ingreso")+SUMIFS(FLEXIBLE!$D$4:$D$200,FLEXIBLE!$F$4:$F$200,A12)) -> 2183.94 | H12: =IF(A12="","",-SUMIFS(MOVIMIENTOS!$E$4:$E$20000,MOVIMIENTOS!$B$4:$B$20000,A12,MOVIMIENTOS!$H$4:$H$20000,"Gasto")+SUMIFS(FLEXIBLE!$D$4:$D$200,FLEXIBLE!$F$4:$F$200,A12)) -> 1640.04 | I12: =IF(A12="","",G12-H12) -> 543.9 | J12: =IF(A12="","",IF(N12=0,"en curso",IF(N(G12)=0,"",I12/G12))) -> 0.2490453 | K12: =IF(A12="","",SUM(B12:F12)) -> 62210.03 | L12: =IF(A12="","",YEAR(A12)) -> 2026 | M12: =IF(A12="","",COUNTIFS(MOVIMIENTOS!$B$4:$B$20000,A12,MOVIMIENTOS!$H$4:$H$20000,"Por revisar")) -> 0 | N12: =IF(A12="","",IF(A12<DATE(YEAR(TODAY()),MONTH(TODAY()),1),1,0)) -> 1
A13: 46143 | B13: 6863.18 | C13: 1287.25 | D13: 54667.34 | E13: 0 | F13: 0 | G13: =IF(A13="","",SUMIFS(MOVIMIENTOS!$E$4:$E$20000,MOVIMIENTOS!$B$4:$B$20000,A13,MOVIMIENTOS!$H$4:$H$20000,"Ingreso")+SUMIFS(FLEXIBLE!$D$4:$D$200,FLEXIBLE!$F$4:$F$200,A13)) -> 2184.15 | H13: =IF(A13="","",-SUMIFS(MOVIMIENTOS!$E$4:$E$20000,MOVIMIENTOS!$B$4:$B$20000,A13,MOVIMIENTOS!$H$4:$H$20000,"Gasto")+SUMIFS(FLEXIBLE!$D$4:$D$200,FLEXIBLE!$F$4:$F$200,A13)) -> 1553.78 | I13: =IF(A13="","",G13-H13) -> 630.37 | J13: =IF(A13="","",IF(N13=0,"en curso",IF(N(G13)=0,"",I13/G13))) -> 0.28861113 | K13: =IF(A13="","",SUM(B13:F13)) -> 62817.77 | L13: =IF(A13="","",YEAR(A13)) -> 2026 | M13: =IF(A13="","",COUNTIFS(MOVIMIENTOS!$B$4:$B$20000,A13,MOVIMIENTOS!$H$4:$H$20000,"Por revisar")) -> 0 | N13: =IF(A13="","",IF(A13<DATE(YEAR(TODAY()),MONTH(TODAY()),1),1,0)) -> 1
A14: 46174 | B14: 9281.91 | C14: 1360.91 | D14: 55001.69 | E14: 0 | F14: 0 | G14: =IF(A14="","",SUMIFS(MOVIMIENTOS!$E$4:$E$20000,MOVIMIENTOS!$B$4:$B$20000,A14,MOVIMIENTOS!$H$4:$H$20000,"Ingreso")+SUMIFS(FLEXIBLE!$D$4:$D$200,FLEXIBLE!$F$4:$F$200,A14)) -> 4492.75 | H14: =IF(A14="","",-SUMIFS(MOVIMIENTOS!$E$4:$E$20000,MOVIMIENTOS!$B$4:$B$20000,A14,MOVIMIENTOS!$H$4:$H$20000,"Gasto")+SUMIFS(FLEXIBLE!$D$4:$D$200,FLEXIBLE!$F$4:$F$200,A14)) -> 1703.73 | I14: =IF(A14="","",G14-H14) -> 2789.02 | J14: =IF(A14="","",IF(N14=0,"en curso",IF(N(G14)=0,"",I14/G14))) -> 0.62078237 | K14: =IF(A14="","",SUM(B14:F14)) -> 65644.51 | L14: =IF(A14="","",YEAR(A14)) -> 2026 | M14: =IF(A14="","",COUNTIFS(MOVIMIENTOS!$B$4:$B$20000,A14,MOVIMIENTOS!$H$4:$H$20000,"Por revisar")) -> 0 | N14: =IF(A14="","",IF(A14<DATE(YEAR(TODAY()),MONTH(TODAY()),1),1,0)) -> 1
A15: 46204 | B15: 9973.79 | C15: 1396.85 | D15: 55336.25 | E15: 0 | F15: 0 | G15: =IF(A15="","",SUMIFS(MOVIMIENTOS!$E$4:$E$20000,MOVIMIENTOS!$B$4:$B$20000,A15,MOVIMIENTOS!$H$4:$H$20000,"Ingreso")+SUMIFS(FLEXIBLE!$D$4:$D$200,FLEXIBLE!$F$4:$F$200,A15)) -> 2768.17 | H15: =IF(A15="","",-SUMIFS(MOVIMIENTOS!$E$4:$E$20000,MOVIMIENTOS!$B$4:$B$20000,A15,MOVIMIENTOS!$H$4:$H$20000,"Gasto")+SUMIFS(FLEXIBLE!$D$4:$D$200,FLEXIBLE!$F$4:$F$200,A15)) -> 1750.81 | I15: =IF(A15="","",G15-H15) -> 1017.36 | J15: =IF(A15="","",IF(N15=0,"en curso",IF(N(G15)=0,"",I15/G15))) -> 0.36752078 | K15: =IF(A15="","",SUM(B15:F15)) -> 66706.89 | L15: =IF(A15="","",YEAR(A15)) -> 2026 | M15: =IF(A15="","",COUNTIFS(MOVIMIENTOS!$B$4:$B$20000,A15,MOVIMIENTOS!$H$4:$H$20000,"Por revisar")) -> 0 | N15: =IF(A15="","",IF(A15<DATE(YEAR(TODAY()),MONTH(TODAY()),1),1,0)) -> 1
A16: 46235 | B16: 10211.08 | C16: 1387.77 | D16: 55671.02 | E16: 0 | F16: 0 | G16: =IF(A16="","",SUMIFS(MOVIMIENTOS!$E$4:$E$20000,MOVIMIENTOS!$B$4:$B$20000,A16,MOVIMIENTOS!$H$4:$H$20000,"Ingreso")+SUMIFS(FLEXIBLE!$D$4:$D$200,FLEXIBLE!$F$4:$F$200,A16)) -> 2300.87 | H16: =IF(A16="","",-SUMIFS(MOVIMIENTOS!$E$4:$E$20000,MOVIMIENTOS!$B$4:$B$20000,A16,MOVIMIENTOS!$H$4:$H$20000,"Gasto")+SUMIFS(FLEXIBLE!$D$4:$D$200,FLEXIBLE!$F$4:$F$200,A16)) -> 1666.68 | I16: =IF(A16="","",G16-H16) -> 634.19 | J16: =IF(A16="","",IF(N16=0,"en curso",IF(N(G16)=0,"",I16/G16))) -> 0.27563052 | K16: =IF(A16="","",SUM(B16:F16)) -> 67269.87 | L16: =IF(A16="","",YEAR(A16)) -> 2026 | M16: =IF(A16="","",COUNTIFS(MOVIMIENTOS!$B$4:$B$20000,A16,MOVIMIENTOS!$H$4:$H$20000,"Por revisar")) -> 0 | N16: =IF(A16="","",IF(A16<DATE(YEAR(TODAY()),MONTH(TODAY()),1),1,0)) -> 1
A17: 46266 | B17: 10501.16 | C17: 1449.9 | D17: 56006 | E17: 0 | F17: 0 | G17: =IF(A17="","",SUMIFS(MOVIMIENTOS!$E$4:$E$20000,MOVIMIENTOS!$B$4:$B$20000,A17,MOVIMIENTOS!$H$4:$H$20000,"Ingreso")+SUMIFS(FLEXIBLE!$D$4:$D$200,FLEXIBLE!$F$4:$F$200,A17)) -> 2349.78 | H17: =IF(A17="","",-SUMIFS(MOVIMIENTOS!$E$4:$E$20000,MOVIMIENTOS!$B$4:$B$20000,A17,MOVIMIENTOS!$H$4:$H$20000,"Gasto")+SUMIFS(FLEXIBLE!$D$4:$D$200,FLEXIBLE!$F$4:$F$200,A17)) -> 1679.46 | I17: =IF(A17="","",G17-H17) -> 670.32 | J17: =IF(A17="","",IF(N17=0,"en curso",IF(N(G17)=0,"",I17/G17))) -> 0.28526926 | K17: =IF(A17="","",SUM(B17:F17)) -> 67957.06 | L17: =IF(A17="","",YEAR(A17)) -> 2026 | M17: =IF(A17="","",COUNTIFS(MOVIMIENTOS!$B$4:$B$20000,A17,MOVIMIENTOS!$H$4:$H$20000,"Por revisar")) -> 2 | N17: =IF(A17="","",IF(A17<DATE(YEAR(TODAY()),MONTH(TODAY()),1),1,0)) -> 1
G18: =IF(A18="","",SUMIFS(MOVIMIENTOS!$E$4:$E$20000,MOVIMIENTOS!$B$4:$B$20000,A18,MOVIMIENTOS!$H$4:$H$20000,"Ingreso")+SUMIFS(FLEXIBLE!$D$4:$D$200,FLEXIBLE!$F$4:$F$200,A18)) | H18: =IF(A18="","",-SUMIFS(MOVIMIENTOS!$E$4:$E$20000,MOVIMIENTOS!$B$4:$B$20000,A18,MOVIMIENTOS!$H$4:$H$20000,"Gasto")+SUMIFS(FLEXIBLE!$D$4:$D$200,FLEXIBLE!$F$4:$F$200,A18)) | I18: =IF(A18="","",G18-H18) | J18: =IF(A18="","",IF(N18=0,"en curso",IF(N(G18)=0,"",I18/G18))) | K18: =IF(A18="","",SUM(B18:F18)) | L18: =IF(A18="","",YEAR(A18)) | M18: =IF(A18="","",COUNTIFS(MOVIMIENTOS!$B$4:$B$20000,A18,MOVIMIENTOS!$H$4:$H$20000,"Por revisar")) | N18: =IF(A18="","",IF(A18<DATE(YEAR(TODAY()),MONTH(TODAY()),1),1,0))
G19: =IF(A19="","",SUMIFS(MOVIMIENTOS!$E$4:$E$20000,MOVIMIENTOS!$B$4:$B$20000,A19,MOVIMIENTOS!$H$4:$H$20000,"Ingreso")+SUMIFS(FLEXIBLE!$D$4:$D$200,FLEXIBLE!$F$4:$F$200,A19)) | H19: =IF(A19="","",-SUMIFS(MOVIMIENTOS!$E$4:$E$20000,MOVIMIENTOS!$B$4:$B$20000,A19,MOVIMIENTOS!$H$4:$H$20000,"Gasto")+SUMIFS(FLEXIBLE!$D$4:$D$200,FLEXIBLE!$F$4:$F$200,A19)) | I19: =IF(A19="","",G19-H19) | J19: =IF(A19="","",IF(N19=0,"en curso",IF(N(G19)=0,"",I19/G19))) | K19: =IF(A19="","",SUM(B19:F19)) | L19: =IF(A19="","",YEAR(A19)) | M19: =IF(A19="","",COUNTIFS(MOVIMIENTOS!$B$4:$B$20000,A19,MOVIMIENTOS!$H$4:$H$20000,"Por revisar")) | N19: =IF(A19="","",IF(A19<DATE(YEAR(TODAY()),MONTH(TODAY()),1),1,0))
G20: =IF(A20="","",SUMIFS(MOVIMIENTOS!$E$4:$E$20000,MOVIMIENTOS!$B$4:$B$20000,A20,MOVIMIENTOS!$H$4:$H$20000,"Ingreso")+SUMIFS(FLEXIBLE!$D$4:$D$200,FLEXIBLE!$F$4:$F$200,A20)) | H20: =IF(A20="","",-SUMIFS(MOVIMIENTOS!$E$4:$E$20000,MOVIMIENTOS!$B$4:$B$20000,A20,MOVIMIENTOS!$H$4:$H$20000,"Gasto")+SUMIFS(FLEXIBLE!$D$4:$D$200,FLEXIBLE!$F$4:$F$200,A20)) | I20: =IF(A20="","",G20-H20) | J20: =IF(A20="","",IF(N20=0,"en curso",IF(N(G20)=0,"",I20/G20))) | K20: =IF(A20="","",SUM(B20:F20)) | L20: =IF(A20="","",YEAR(A20)) | M20: =IF(A20="","",COUNTIFS(MOVIMIENTOS!$B$4:$B$20000,A20,MOVIMIENTOS!$H$4:$H$20000,"Por revisar")) | N20: =IF(A20="","",IF(A20<DATE(YEAR(TODAY()),MONTH(TODAY()),1),1,0))
G21: =IF(A21="","",SUMIFS(MOVIMIENTOS!$E$4:$E$20000,MOVIMIENTOS!$B$4:$B$20000,A21,MOVIMIENTOS!$H$4:$H$20000,"Ingreso")+SUMIFS(FLEXIBLE!$D$4:$D$200,FLEXIBLE!$F$4:$F$200,A21)) | H21: =IF(A21="","",-SUMIFS(MOVIMIENTOS!$E$4:$E$20000,MOVIMIENTOS!$B$4:$B$20000,A21,MOVIMIENTOS!$H$4:$H$20000,"Gasto")+SUMIFS(FLEXIBLE!$D$4:$D$200,FLEXIBLE!$F$4:$F$200,A21)) | I21: =IF(A21="","",G21-H21) | J21: =IF(A21="","",IF(N21=0,"en curso",IF(N(G21)=0,"",I21/G21))) | K21: =IF(A21="","",SUM(B21:F21)) | L21: =IF(A21="","",YEAR(A21)) | M21: =IF(A21="","",COUNTIFS(MOVIMIENTOS!$B$4:$B$20000,A21,MOVIMIENTOS!$H$4:$H$20000,"Por revisar")) | N21: =IF(A21="","",IF(A21<DATE(YEAR(TODAY()),MONTH(TODAY()),1),1,0))
G22: =IF(A22="","",SUMIFS(MOVIMIENTOS!$E$4:$E$20000,MOVIMIENTOS!$B$4:$B$20000,A22,MOVIMIENTOS!$H$4:$H$20000,"Ingreso")+SUMIFS(FLEXIBLE!$D$4:$D$200,FLEXIBLE!$F$4:$F$200,A22)) | H22: =IF(A22="","",-SUMIFS(MOVIMIENTOS!$E$4:$E$20000,MOVIMIENTOS!$B$4:$B$20000,A22,MOVIMIENTOS!$H$4:$H$20000,"Gasto")+SUMIFS(FLEXIBLE!$D$4:$D$200,FLEXIBLE!$F$4:$F$200,A22)) | I22: =IF(A22="","",G22-H22) | J22: =IF(A22="","",IF(N22=0,"en curso",IF(N(G22)=0,"",I22/G22))) | K22: =IF(A22="","",SUM(B22:F22)) | L22: =IF(A22="","",YEAR(A22)) | M22: =IF(A22="","",COUNTIFS(MOVIMIENTOS!$B$4:$B$20000,A22,MOVIMIENTOS!$H$4:$H$20000,"Por revisar")) | N22: =IF(A22="","",IF(A22<DATE(YEAR(TODAY()),MONTH(TODAY()),1),1,0))
G23: =IF(A23="","",SUMIFS(MOVIMIENTOS!$E$4:$E$20000,MOVIMIENTOS!$B$4:$B$20000,A23,MOVIMIENTOS!$H$4:$H$20000,"Ingreso")+SUMIFS(FLEXIBLE!$D$4:$D$200,FLEXIBLE!$F$4:$F$200,A23)) | H23: =IF(A23="","",-SUMIFS(MOVIMIENTOS!$E$4:$E$20000,MOVIMIENTOS!$B$4:$B$20000,A23,MOVIMIENTOS!$H$4:$H$20000,"Gasto")+SUMIFS(FLEXIBLE!$D$4:$D$200,FLEXIBLE!$F$4:$F$200,A23)) | I23: =IF(A23="","",G23-H23) | J23: =IF(A23="","",IF(N23=0,"en curso",IF(N(G23)=0,"",I23/G23))) | K23: =IF(A23="","",SUM(B23:F23)) | L23: =IF(A23="","",YEAR(A23)) | M23: =IF(A23="","",COUNTIFS(MOVIMIENTOS!$B$4:$B$20000,A23,MOVIMIENTOS!$H$4:$H$20000,"Por revisar")) | N23: =IF(A23="","",IF(A23<DATE(YEAR(TODAY()),MONTH(TODAY()),1),1,0))
G24: =IF(A24="","",SUMIFS(MOVIMIENTOS!$E$4:$E$20000,MOVIMIENTOS!$B$4:$B$20000,A24,MOVIMIENTOS!$H$4:$H$20000,"Ingreso")+SUMIFS(FLEXIBLE!$D$4:$D$200,FLEXIBLE!$F$4:$F$200,A24)) | H24: =IF(A24="","",-SUMIFS(MOVIMIENTOS!$E$4:$E$20000,MOVIMIENTOS!$B$4:$B$20000,A24,MOVIMIENTOS!$H$4:$H$20000,"Gasto")+SUMIFS(FLEXIBLE!$D$4:$D$200,FLEXIBLE!$F$4:$F$200,A24)) | I24: =IF(A24="","",G24-H24) | J24: =IF(A24="","",IF(N24=0,"en curso",IF(N(G24)=0,"",I24/G24))) | K24: =IF(A24="","",SUM(B24:F24)) | L24: =IF(A24="","",YEAR(A24)) | M24: =IF(A24="","",COUNTIFS(MOVIMIENTOS!$B$4:$B$20000,A24,MOVIMIENTOS!$H$4:$H$20000,"Por revisar")) | N24: =IF(A24="","",IF(A24<DATE(YEAR(TODAY()),MONTH(TODAY()),1),1,0))
G25: =IF(A25="","",SUMIFS(MOVIMIENTOS!$E$4:$E$20000,MOVIMIENTOS!$B$4:$B$20000,A25,MOVIMIENTOS!$H$4:$H$20000,"Ingreso")+SUMIFS(FLEXIBLE!$D$4:$D$200,FLEXIBLE!$F$4:$F$200,A25)) | H25: =IF(A25="","",-SUMIFS(MOVIMIENTOS!$E$4:$E$20000,MOVIMIENTOS!$B$4:$B$20000,A25,MOVIMIENTOS!$H$4:$H$20000,"Gasto")+SUMIFS(FLEXIBLE!$D$4:$D$200,FLEXIBLE!$F$4:$F$200,A25)) | I25: =IF(A25="","",G25-H25) | J25: =IF(A25="","",IF(N25=0,"en curso",IF(N(G25)=0,"",I25/G25))) | K25: =IF(A25="","",SUM(B25:F25)) | L25: =IF(A25="","",YEAR(A25)) | M25: =IF(A25="","",COUNTIFS(MOVIMIENTOS!$B$4:$B$20000,A25,MOVIMIENTOS!$H$4:$H$20000,"Por revisar")) | N25: =IF(A25="","",IF(A25<DATE(YEAR(TODAY()),MONTH(TODAY()),1),1,0))
G26: =IF(A26="","",SUMIFS(MOVIMIENTOS!$E$4:$E$20000,MOVIMIENTOS!$B$4:$B$20000,A26,MOVIMIENTOS!$H$4:$H$20000,"Ingreso")+SUMIFS(FLEXIBLE!$D$4:$D$200,FLEXIBLE!$F$4:$F$200,A26)) | H26: =IF(A26="","",-SUMIFS(MOVIMIENTOS!$E$4:$E$20000,MOVIMIENTOS!$B$4:$B$20000,A26,MOVIMIENTOS!$H$4:$H$20000,"Gasto")+SUMIFS(FLEXIBLE!$D$4:$D$200,FLEXIBLE!$F$4:$F$200,A26)) | I26: =IF(A26="","",G26-H26) | J26: =IF(A26="","",IF(N26=0,"en curso",IF(N(G26)=0,"",I26/G26))) | K26: =IF(A26="","",SUM(B26:F26)) | L26: =IF(A26="","",YEAR(A26)) | M26: =IF(A26="","",COUNTIFS(MOVIMIENTOS!$B$4:$B$20000,A26,MOVIMIENTOS!$H$4:$H$20000,"Por revisar")) | N26: =IF(A26="","",IF(A26<DATE(YEAR(TODAY()),MONTH(TODAY()),1),1,0))
G27: =IF(A27="","",SUMIFS(MOVIMIENTOS!$E$4:$E$20000,MOVIMIENTOS!$B$4:$B$20000,A27,MOVIMIENTOS!$H$4:$H$20000,"Ingreso")+SUMIFS(FLEXIBLE!$D$4:$D$200,FLEXIBLE!$F$4:$F$200,A27)) | H27: =IF(A27="","",-SUMIFS(MOVIMIENTOS!$E$4:$E$20000,MOVIMIENTOS!$B$4:$B$20000,A27,MOVIMIENTOS!$H$4:$H$20000,"Gasto")+SUMIFS(FLEXIBLE!$D$4:$D$200,FLEXIBLE!$F$4:$F$200,A27)) | I27: =IF(A27="","",G27-H27) | J27: =IF(A27="","",IF(N27=0,"en curso",IF(N(G27)=0,"",I27/G27))) | K27: =IF(A27="","",SUM(B27:F27)) | L27: =IF(A27="","",YEAR(A27)) | M27: =IF(A27="","",COUNTIFS(MOVIMIENTOS!$B$4:$B$20000,A27,MOVIMIENTOS!$H$4:$H$20000,"Por revisar")) | N27: =IF(A27="","",IF(A27<DATE(YEAR(TODAY()),MONTH(TODAY()),1),1,0))
G28: =IF(A28="","",SUMIFS(MOVIMIENTOS!$E$4:$E$20000,MOVIMIENTOS!$B$4:$B$20000,A28,MOVIMIENTOS!$H$4:$H$20000,"Ingreso")+SUMIFS(FLEXIBLE!$D$4:$D$200,FLEXIBLE!$F$4:$F$200,A28)) | H28: =IF(A28="","",-SUMIFS(MOVIMIENTOS!$E$4:$E$20000,MOVIMIENTOS!$B$4:$B$20000,A28,MOVIMIENTOS!$H$4:$H$20000,"Gasto")+SUMIFS(FLEXIBLE!$D$4:$D$200,FLEXIBLE!$F$4:$F$200,A28)) | I28: =IF(A28="","",G28-H28) | J28: =IF(A28="","",IF(N28=0,"en curso",IF(N(G28)=0,"",I28/G28))) | K28: =IF(A28="","",SUM(B28:F28)) | L28: =IF(A28="","",YEAR(A28)) | M28: =IF(A28="","",COUNTIFS(MOVIMIENTOS!$B$4:$B$20000,A28,MOVIMIENTOS!$H$4:$H$20000,"Por revisar")) | N28: =IF(A28="","",IF(A28<DATE(YEAR(TODAY()),MONTH(TODAY()),1),1,0))
G29: =IF(A29="","",SUMIFS(MOVIMIENTOS!$E$4:$E$20000,MOVIMIENTOS!$B$4:$B$20000,A29,MOVIMIENTOS!$H$4:$H$20000,"Ingreso")+SUMIFS(FLEXIBLE!$D$4:$D$200,FLEXIBLE!$F$4:$F$200,A29)) | H29: =IF(A29="","",-SUMIFS(MOVIMIENTOS!$E$4:$E$20000,MOVIMIENTOS!$B$4:$B$20000,A29,MOVIMIENTOS!$H$4:$H$20000,"Gasto")+SUMIFS(FLEXIBLE!$D$4:$D$200,FLEXIBLE!$F$4:$F$200,A29)) | I29: =IF(A29="","",G29-H29) | J29: =IF(A29="","",IF(N29=0,"en curso",IF(N(G29)=0,"",I29/G29))) | K29: =IF(A29="","",SUM(B29:F29)) | L29: =IF(A29="","",YEAR(A29)) | M29: =IF(A29="","",COUNTIFS(MOVIMIENTOS!$B$4:$B$20000,A29,MOVIMIENTOS!$H$4:$H$20000,"Por revisar")) | N29: =IF(A29="","",IF(A29<DATE(YEAR(TODAY()),MONTH(TODAY()),1),1,0))
... G245: =IF(A245="","",SUMIFS(MOVIMIENTOS!$E$4:$E$20000,MOVIMIENTOS!$B$4:$B$20000,A245,MOVIMIENTOS!$H$4:$H$20000,"Ingreso")+SUMIFS(FLEXIBLE!$D$4:$D$200,FLEXIBLE!$F$4:$F$200,A245)) | H245: =IF(A245="","",-SUMIFS(MOVIMIENTOS!$E$4:$E$20000,MOVIMIENTOS!$B$4:$B$20000,A245,MOVIMIENTOS!$H$4:$H$20000,"Gasto")+SUMIFS(FLEXIBLE!$D$4:$D$200,FLEXIBLE!$F$4:$F$200,A245)) | I245: =IF(A245="","",G245-H245) | J245: =IF(A245="","",IF(N245=0,"en curso",IF(N(G245)=0,"",I245/G245))) | K245: =IF(A245="","",SUM(B245:F245)) | L245: =IF(A245="","",YEAR(A245)) | M245: =IF(A245="","",COUNTIFS(MOVIMIENTOS!$B$4:$B$20000,A245,MOVIMIENTOS!$H$4:$H$20000,"Por revisar")) | N245: =IF(A245="","",IF(A245<DATE(YEAR(TODAY()),MONTH(TODAY()),1),1,0))

Sheet MOVIMIENTOS
A1: MOVIMIENTOS
A2: Los trae el importador (menú Plan financiero). Tú solo cambias Categoría y escribes Nota; lo amarillo está por revisar.
A3: Fecha | B3: Mes | C3: Cuenta | D3: Concepto | E3: Importe | F3: Saldo | G3: Categoría | H3: Tipo | I3: Grupo | J3: Nota | K3: Clave
A4: 46295 | B4: =DATE(YEAR(A4),MONTH(A4),1) -> 46266 | C4: ING | D4: INTERESES CUENTA AHORRO | E4: 34.98 | F4: 56006 | G4: Intereses | H4: =IFERROR(VLOOKUP(G4,CATEGORÍAS!$A$4:$C$100,2,FALSE()),"Por revisar") -> Ingreso | I4: =IFERROR(VLOOKUP(G4,CATEGORÍAS!$A$4:$C$100,3,FALSE()),"") -> Ahorro | K4: ING|2026-09-30||34.98|56006.00#1
A5: 46293 | B5: =DATE(YEAR(A5),MONTH(A5),1) -> 46266 | C5: CaixaBank | D5: NOMINA EMPRESA EJEMPLO SL | E5: 2150 | F5: 10501.16 | G5: Nómina | H5: =IFERROR(VLOOKUP(G5,CATEGORÍAS!$A$4:$C$100,2,FALSE()),"Por revisar") -> Ingreso | I5: =IFERROR(VLOOKUP(G5,CATEGORÍAS!$A$4:$C$100,3,FALSE()),"") -> Trabajo | K5: CaixaBank|2026-09-28||2150.00|10501.16#1
A6: 46292 | B6: =DATE(YEAR(A6),MONTH(A6),1) -> 46266 | C6: Openbank tarjeta | D6: FRUTERIA LA HUERTA | E6: -11.6 | G6: Supermercado | H6: =IFERROR(VLOOKUP(G6,CATEGORÍAS!$A$4:$C$100,2,FALSE()),"Por revisar") -> Gasto | I6: =IFERROR(VLOOKUP(G6,CATEGORÍAS!$A$4:$C$100,3,FALSE()),"") -> Comida | K6: Openbank tarjeta|2026-09-27|20:00|-11.60|#1
A7: 46292 | B7: =DATE(YEAR(A7),MONTH(A7),1) -> 46266 | C7: Openbank tarjeta | D7: CAFETERIA CENTRAL | E7: -7.97 | G7: Restaurantes y caprichos | H7: =IFERROR(VLOOKUP(G7,CATEGORÍAS!$A$4:$C$100,2,FALSE()),"Por revisar") -> Gasto | I7: =IFERROR(VLOOKUP(G7,CATEGORÍAS!$A$4:$C$100,3,FALSE()),"") -> Comida | K7: Openbank tarjeta|2026-09-27|11:07|-7.97|#1
A8: 46289 | B8: =DATE(YEAR(A8),MONTH(A8),1) -> 46266 | C8: Openbank tarjeta | D8: RESTAURANTE LA PLAZA | E8: -37.23 | G8: Restaurantes y caprichos | H8: =IFERROR(VLOOKUP(G8,CATEGORÍAS!$A$4:$C$100,2,FALSE()),"Por revisar") -> Gasto | I8: =IFERROR(VLOOKUP(G8,CATEGORÍAS!$A$4:$C$100,3,FALSE()),"") -> Comida | K8: Openbank tarjeta|2026-09-24|21:15|-37.23|#1
A9: 46289 | B9: =DATE(YEAR(A9),MONTH(A9),1) -> 46266 | C9: Openbank tarjeta | D9: TRANSPORTE PUBLICO RECARGA | E9: -20 | G9: Transporte | H9: =IFERROR(VLOOKUP(G9,CATEGORÍAS!$A$4:$C$100,2,FALSE()),"Por revisar") -> Gasto | I9: =IFERROR(VLOOKUP(G9,CATEGORÍAS!$A$4:$C$100,3,FALSE()),"") -> Transporte | K9: Openbank tarjeta|2026-09-24|16:31|-20.00|#1
A10: 46289 | B10: =DATE(YEAR(A10),MONTH(A10),1) -> 46266 | C10: CaixaBank | D10: BIZUM CENA | E10: 19 | F10: 8351.16 | G10: ❓ Por revisar | H10: =IFERROR(VLOOKUP(G10,CATEGORÍAS!$A$4:$C$100,2,FALSE()),"Por revisar") -> Por revisar | I10: =IFERROR(VLOOKUP(G10,CATEGORÍAS!$A$4:$C$100,3,FALSE()),"") -> 0 | K10: CaixaBank|2026-09-24||19.00|8351.16#1
A11: 46288 | B11: =DATE(YEAR(A11),MONTH(A11),1) -> 46266 | C11: Openbank tarjeta | D11: TIENDA ONLINE | E11: -44.59 | G11: Compras online | H11: =IFERROR(VLOOKUP(G11,CATEGORÍAS!$A$4:$C$100,2,FALSE()),"Por revisar") -> Gasto | I11: =IFERROR(VLOOKUP(G11,CATEGORÍAS!$A$4:$C$100,3,FALSE()),"") -> Personal | K11: Openbank tarjeta|2026-09-23|19:07|-44.59|#1
A12: 46288 | B12: =DATE(YEAR(A12),MONTH(A12),1) -> 46266 | C12: Openbank tarjeta | D12: RESTAURANTE LA PLAZA | E12: -29.53 | G12: Restaurantes y caprichos | H12: =IFERROR(VLOOKUP(G12,CATEGORÍAS!$A$4:$C$100,2,FALSE()),"Por revisar") -> Gasto | I12: =IFERROR(VLOOKUP(G12,CATEGORÍAS!$A$4:$C$100,3,FALSE()),"") -> Comida | K12: Openbank tarjeta|2026-09-23|12:45|-29.53|#1
A13: 46287 | B13: =DATE(YEAR(A13),MONTH(A13),1) -> 46266 | C13: Openbank tarjeta | D13: CAFETERIA CENTRAL | E13: -8.79 | G13: Restaurantes y caprichos | H13: =IFERROR(VLOOKUP(G13,CATEGORÍAS!$A$4:$C$100,2,FALSE()),"Por revisar") -> Gasto | I13: =IFERROR(VLOOKUP(G13,CATEGORÍAS!$A$4:$C$100,3,FALSE()),"") -> Comida | K13: Openbank tarjeta|2026-09-22|11:15|-8.79|#1
A14: 46287 | B14: =DATE(YEAR(A14),MONTH(A14),1) -> 46266 | C14: CaixaBank | D14: PELUQUERIA ESTILO | E14: -22 | F14: 8332.16 | G14: Cuidado personal | H14: =IFERROR(VLOOKUP(G14,CATEGORÍAS!$A$4:$C$100,2,FALSE()),"Por revisar") -> Gasto | I14: =IFERROR(VLOOKUP(G14,CATEGORÍAS!$A$4:$C$100,3,FALSE()),"") -> Personal | K14: CaixaBank|2026-09-22||-22.00|8332.16#1
A15: 46284 | B15: =DATE(YEAR(A15),MONTH(A15),1) -> 46266 | C15: Openbank tarjeta | D15: FRUTERIA LA HUERTA | E15: -19.81 | G15: Supermercado | H15: =IFERROR(VLOOKUP(G15,CATEGORÍAS!$A$4:$C$100,2,FALSE()),"Por revisar") -> Gasto | I15: =IFERROR(VLOOKUP(G15,CATEGORÍAS!$A$4:$C$100,3,FALSE()),"") -> Comida | K15: Openbank tarjeta|2026-09-19|19:52|-19.81|#1
A16: 46282 | B16: =DATE(YEAR(A16),MONTH(A16),1) -> 46266 | C16: Openbank tarjeta | D16: SUPERMERCADO EL BARRIO | E16: -36.94 | G16: Supermercado | H16: =IFERROR(VLOOKUP(G16,CATEGORÍAS!$A$4:$C$100,2,FALSE()),"Por revisar") -> Gasto | I16: =IFERROR(VLOOKUP(G16,CATEGORÍAS!$A$4:$C$100,3,FALSE()),"") -> Comida | K16: Openbank tarjeta|2026-09-17|16:00|-36.94|#1
A17: 46281 | B17: =DATE(YEAR(A17),MONTH(A17),1) -> 46266 | C17: Openbank tarjeta | D17: GASOLINERA RUTA | E17: -36.84 | G17: Transporte | H17: =IFERROR(VLOOKUP(G17,CATEGORÍAS!$A$4:$C$100,2,FALSE()),"Por revisar") -> Gasto | I17: =IFERROR(VLOOKUP(G17,CATEGORÍAS!$A$4:$C$100,3,FALSE()),"") -> Transporte | K17: Openbank tarjeta|2026-09-16|11:45|-36.84|#1
A18: 46281 | B18: =DATE(YEAR(A18),MONTH(A18),1) -> 46266 | C18: Openbank tarjeta | D18: SUPERMERCADO EL BARRIO | E18: -18.39 | G18: Supermercado | H18: =IFERROR(VLOOKUP(G18,CATEGORÍAS!$A$4:$C$100,2,FALSE()),"Por revisar") -> Gasto | I18: =IFERROR(VLOOKUP(G18,CATEGORÍAS!$A$4:$C$100,3,FALSE()),"") -> Comida | K18: Openbank tarjeta|2026-09-16|09:15|-18.39|#1
A19: 46280 | B19: =DATE(YEAR(A19),MONTH(A19),1) -> 46266 | C19: Openbank tarjeta | D19: SUPERMERCADO EL BARRIO | E19: -53.38 | G19: Supermercado | H19: =IFERROR(VLOOKUP(G19,CATEGORÍAS!$A$4:$C$100,2,FALSE()),"Por revisar") -> Gasto | I19: =IFERROR(VLOOKUP(G19,CATEGORÍAS!$A$4:$C$100,3,FALSE()),"") -> Comida | K19: Openbank tarjeta|2026-09-15|14:07|-53.38|#1
A20: 46276 | B20: =DATE(YEAR(A20),MONTH(A20),1) -> 46266 | C20: Openbank tarjeta | D20: SUPERMERCADO EL BARRIO | E20: -25.57 | G20: Supermercado | H20: =IFERROR(VLOOKUP(G20,CATEGORÍAS!$A$4:$C$100,2,FALSE()),"Por revisar") -> Gasto | I20: =IFERROR(VLOOKUP(G20,CATEGORÍAS!$A$4:$C$100,3,FALSE()),"") -> Comida | K20: Openbank tarjeta|2026-09-11|16:00|-25.57|#1
A21: 46276 | B21: =DATE(YEAR(A21),MONTH(A21),1) -> 46266 | C21: CaixaBank | D21: BIZUM COMIDA DOMINGO | E21: 29 | F21: 8354.16 | G21: ❓ Por revisar | H21: =IFERROR(VLOOKUP(G21,CATEGORÍAS!$A$4:$C$100,2,FALSE()),"Por revisar") -> Por revisar | I21: =IFERROR(VLOOKUP(G21,CATEGORÍAS!$A$4:$C$100,3,FALSE()),"") -> 0 | K21: CaixaBank|2026-09-11||29.00|8354.16#1
A22: 46274 | B22: =DATE(YEAR(A22),MONTH(A22),1) -> 46266 | C22: CaixaBank | D22: RECIBO STREAMFLIX | E22: -12.99 | F22: 8325.16 | G22: Suscripciones | H22: =IFERROR(VLOOKUP(G22,CATEGORÍAS!$A$4:$C$100,2,FALSE()),"Por revisar") -> Gasto | I22: =IFERROR(VLOOKUP(G22,CATEGORÍAS!$A$4:$C$100,3,FALSE()),"") -> Personal | K22: CaixaBank|2026-09-09||-12.99|8325.16#1
A23: 46273 | B23: =DATE(YEAR(A23),MONTH(A23),1) -> 46266 | C23: CaixaBank | D23: RECIBO LUZ HOGAR ENERGIA | E23: -38.08 | F23: 8338.15 | G23: Luz y gas | H23: =IFERROR(VLOOKUP(G23,CATEGORÍAS!$A$4:$C$100,2,FALSE()),"Por revisar") -> Gasto | I23: =IFERROR(VLOOKUP(G23,CATEGORÍAS!$A$4:$C$100,3,FALSE()),"") -> Casa | K23: CaixaBank|2026-09-08||-38.08|8338.15#1
A24: 46272 | B24: =DATE(YEAR(A24),MONTH(A24),1) -> 46266 | C24: Openbank tarjeta | D24: FARMACIA SAN JOSE | E24: -8.55 | G24: Salud y farmacia | H24: =IFERROR(VLOOKUP(G24,CATEGORÍAS!$A$4:$C$100,2,FALSE()),"Por revisar") -> Gasto | I24: =IFERROR(VLOOKUP(G24,CATEGORÍAS!$A$4:$C$100,3,FALSE()),"") -> Salud | K24: Openbank tarjeta|2026-09-07|09:15|-8.55|#1
A25: 46271 | B25: =DATE(YEAR(A25),MONTH(A25),1) -> 46266 | C25: Openbank tarjeta | D25: CAFETERIA CENTRAL | E25: -5.77 | G25: Restaurantes y caprichos | H25: =IFERROR(VLOOKUP(G25,CATEGORÍAS!$A$4:$C$100,2,FALSE()),"Por revisar") -> Gasto | I25: =IFERROR(VLOOKUP(G25,CATEGORÍAS!$A$4:$C$100,3,FALSE()),"") -> Comida | K25: Openbank tarjeta|2026-09-06|21:52|-5.77|#1
A26: 46271 | B26: =DATE(YEAR(A26),MONTH(A26),1) -> 46266 | C26: Openbank tarjeta | D26: CAFETERIA CENTRAL | E26: -5.98 | G26: Restaurantes y caprichos | H26: =IFERROR(VLOOKUP(G26,CATEGORÍAS!$A$4:$C$100,2,FALSE()),"Por revisar") -> Gasto | I26: =IFERROR(VLOOKUP(G26,CATEGORÍAS!$A$4:$C$100,3,FALSE()),"") -> Comida | K26: Openbank tarjeta|2026-09-06|21:22|-5.98|#1
A27: 46271 | B27: =DATE(YEAR(A27),MONTH(A27),1) -> 46266 | C27: CaixaBank | D27: RECIBO MOVILCOM | E27: -14.95 | F27: 8376.23 | G27: Móvil | H27: =IFERROR(VLOOKUP(G27,CATEGORÍAS!$A$4:$C$100,2,FALSE()),"Por revisar") -> Gasto | I27: =IFERROR(VLOOKUP(G27,CATEGORÍAS!$A$4:$C$100,3,FALSE()),"") -> Personal | K27: CaixaBank|2026-09-06||-14.95|8376.23#1
A28: 46270 | B28: =DATE(YEAR(A28),MONTH(A28),1) -> 46266 | C28: CaixaBank | D28: RECIBO FIBRANET | E28: -39.9 | F28: 8391.18 | G28: Internet y teléfono fijo | H28: =IFERROR(VLOOKUP(G28,CATEGORÍAS!$A$4:$C$100,2,FALSE()),"Por revisar") -> Gasto | I28: =IFERROR(VLOOKUP(G28,CATEGORÍAS!$A$4:$C$100,3,FALSE()),"") -> Casa | K28: CaixaBank|2026-09-05||-39.90|8391.18#1
A29: 46270 | B29: =DATE(YEAR(A29),MONTH(A29),1) -> 46266 | C29: Openbank | D29: LIQUIDACION TARJETA CREDITO | E29: -417.87 | F29: 1449.9 | G29: Pago de la tarjeta | H29: =IFERROR(VLOOKUP(G29,CATEGORÍAS!$A$4:$C$100,2,FALSE()),"Por revisar") -> Traspaso | I29: =IFERROR(VLOOKUP(G29,CATEGORÍAS!$A$4:$C$100,3,FALSE()),"") -> Traspasos | K29: Openbank|2026-09-05||-417.87|1449.90#1
A30: 46269 | B30: =DATE(YEAR(A30),MONTH(A30),1) -> 46266 | C30: Openbank tarjeta | D30: CINE ESTRENOS | E30: -10.55 | G30: Ocio y cultura | H30: =IFERROR(VLOOKUP(G30,CATEGORÍAS!$A$4:$C$100,2,FALSE()),"Por revisar") -> Gasto | I30: =IFERROR(VLOOKUP(G30,CATEGORÍAS!$A$4:$C$100,3,FALSE()),"") -> Ocio | K30: Openbank tarjeta|2026-09-04|18:22|-10.55|#1
A31: 46268 | B31: =DATE(YEAR(A31),MONTH(A31),1) -> 46266 | C31: Openbank tarjeta | D31: CAFETERIA CENTRAL | E31: -5.25 | G31: Restaurantes y caprichos | H31: =IFERROR(VLOOKUP(G31,CATEGORÍAS!$A$4:$C$100,2,FALSE()),"Por revisar") -> Gasto | I31: =IFERROR(VLOOKUP(G31,CATEGORÍAS!$A$4:$C$100,3,FALSE()),"") -> Comida | K31: Openbank tarjeta|2026-09-03|14:07|-5.25|#1
A32: 46268 | B32: =DATE(YEAR(A32),MONTH(A32),1) -> 46266 | C32: CaixaBank | D32: TRANSFERENCIA CUENTA DE VIAJES | E32: -150 | F32: 8431.08 | G32: Aportación a la cuenta de viajes | H32: =IFERROR(VLOOKUP(G32,CATEGORÍAS!$A$4:$C$100,2,FALSE()),"Por revisar") -> Gasto | I32: =IFERROR(VLOOKUP(G32,CATEGORÍAS!$A$4:$C$100,3,FALSE()),"") -> Viajes | K32: CaixaBank|2026-09-03||-150.00|8431.08#1
A33: 46267 | B33: =DATE(YEAR(A33),MONTH(A33),1) -> 46266 | C33: CaixaBank | D33: TRASPASO A CUENTA AHORRO ING | E33: -300 | F33: 9061.08 | G33: Traspaso entre mis cuentas | H33: =IFERROR(VLOOKUP(G33,CATEGORÍAS!$A$4:$C$100,2,FALSE()),"Por revisar") -> Traspaso | I33: =IFERROR(VLOOKUP(G33,CATEGORÍAS!$A$4:$C$100,3,FALSE()),"") -> Traspasos | K33: CaixaBank|2026-09-02||-300.00|9061.08#1
A34: 46267 | B34: =DATE(YEAR(A34),MONTH(A34),1) -> 46266 | C34: CaixaBank | D34: TRASPASO A OPENBANK | E34: -480 | F34: 8581.08 | G34: Traspaso entre mis cuentas | H34: =IFERROR(VLOOKUP(G34,CATEGORÍAS!$A$4:$C$100,2,FALSE()),"Por revisar") -> Traspaso | I34: =IFERROR(VLOOKUP(G34,CATEGORÍAS!$A$4:$C$100,3,FALSE()),"") -> Traspasos | K34: CaixaBank|2026-09-02||-480.00|8581.08#1
A35: 46267 | B35: =DATE(YEAR(A35),MONTH(A35),1) -> 46266 | C35: ING | D35: TRASPASO DESDE CAIXABANK | E35: 300 | F35: 55971.02 | G35: Traspaso entre mis cuentas | H35: =IFERROR(VLOOKUP(G35,CATEGORÍAS!$A$4:$C$100,2,FALSE()),"Por revisar") -> Traspaso | I35: =IFERROR(VLOOKUP(G35,CATEGORÍAS!$A$4:$C$100,3,FALSE()),"") -> Traspasos | K35: ING|2026-09-02||300.00|55971.02#1
A36: 46267 | B36: =DATE(YEAR(A36),MONTH(A36),1) -> 46266 | C36: Openbank | D36: TRASPASO DESDE CAIXABANK | E36: 480 | F36: 1867.77 | G36: Traspaso entre mis cuentas | H36: =IFERROR(VLOOKUP(G36,CATEGORÍAS!$A$4:$C$100,2,FALSE()),"Por revisar") -> Traspaso | I36: =IFERROR(VLOOKUP(G36,CATEGORÍAS!$A$4:$C$100,3,FALSE()),"") -> Traspasos | K36: Openbank|2026-09-02||480.00|1867.77#1
A37: 46266 | B37: =DATE(YEAR(A37),MONTH(A37),1) -> 46266 | C37: CaixaBank | D37: ALQUILER VIVIENDA 09/2026 | E37: -850 | F37: 9361.08 | G37: Alquiler | H37: =IFERROR(VLOOKUP(G37,CATEGORÍAS!$A$4:$C$100,2,FALSE()),"Por revisar") -> Gasto | I37: =IFERROR(VLOOKUP(G37,CATEGORÍAS!$A$4:$C$100,3,FALSE()),"") -> Casa | K37: CaixaBank|2026-09-01||-850.00|9361.08#1
A38: 46265 | B38: =DATE(YEAR(A38),MONTH(A38),1) -> 46235 | C38: ING | D38: INTERESES CUENTA AHORRO | E38: 34.77 | F38: 55671.02 | G38: Intereses | H38: =IFERROR(VLOOKUP(G38,CATEGORÍAS!$A$4:$C$100,2,FALSE()),"Por revisar") -> Ingreso | I38: =IFERROR(VLOOKUP(G38,CATEGORÍAS!$A$4:$C$100,3,FALSE()),"") -> Ahorro | K38: ING|2026-08-31||34.77|55671.02#1
A39: 46262 | B39: =DATE(YEAR(A39),MONTH(A39),1) -> 46235 | C39: Openbank tarjeta | D39: FRUTERIA LA HUERTA | E39: -15.37 | G39: Supermercado | H39: =IFERROR(VLOOKUP(G39,CATEGORÍAS!$A$4:$C$100,2,FALSE()),"Por revisar") -> Gasto | I39: =IFERROR(VLOOKUP(G39,CATEGORÍAS!$A$4:$C$100,3,FALSE()),"") -> Comida | K39: Openbank tarjeta|2026-08-28|16:07|-15.37|#1
A40: 46262 | B40: =DATE(YEAR(A40),MONTH(A40),1) -> 46235 | C40: CaixaBank | D40: NOMINA EMPRESA EJEMPLO SL | E40: 2150 | F40: 10211.08 | G40: Nómina | H40: =IFERROR(VLOOKUP(G40,CATEGORÍAS!$A$4:$C$100,2,FALSE()),"Por revisar") -> Ingreso | I40: =IFERROR(VLOOKUP(G40,CATEGORÍAS!$A$4:$C$100,3,FALSE()),"") -> Trabajo | K40: CaixaBank|2026-08-28||2150.00|10211.08#1
...

Sheet FLEXIBLE
A1: FLEXIBLE · retribución flexible
A2: Lo que gastas con la tarjeta de retribución flexible de tu empresa y se descuenta de la nómina. Copia cada mes esas líneas de tu nómina. Cuenta a la vez como ingreso y como gasto: tu ahorro no cambia, tus gastos reales sí.
A3: Mes de la nómina | B3: Comida | C3: Transporte | D3: Total | E3: Nota | F3: mes (calc)
A4: 46174 | B4: 118.4 | C4: 40 | D4: =IF(A4="","",N(B4)+N(C4)) -> 158.4 | E4: Nómina de junio | F4: =IF(A4="","",DATE(YEAR(A4),MONTH(A4),1)) -> 46174
A5: 46204 | B5: 131.25 | C5: 40 | D5: =IF(A5="","",N(B5)+N(C5)) -> 171.25 | E5: Nómina de julio | F5: =IF(A5="","",DATE(YEAR(A5),MONTH(A5),1)) -> 46204
A6: 46235 | B6: 96.1 | C6: 20 | D6: =IF(A6="","",N(B6)+N(C6)) -> 116.1 | E6: Agosto, vacaciones | F6: =IF(A6="","",DATE(YEAR(A6),MONTH(A6),1)) -> 46235
A7: 46266 | B7: 124.8 | C7: 40 | D7: =IF(A7="","",N(B7)+N(C7)) -> 164.8 | E7: Nómina de septiembre | F7: =IF(A7="","",DATE(YEAR(A7),MONTH(A7),1)) -> 46266
D8: =IF(A8="","",N(B8)+N(C8)) | F8: =IF(A8="","",DATE(YEAR(A8),MONTH(A8),1))
D9: =IF(A9="","",N(B9)+N(C9)) | F9: =IF(A9="","",DATE(YEAR(A9),MONTH(A9),1))
D10: =IF(A10="","",N(B10)+N(C10)) | F10: =IF(A10="","",DATE(YEAR(A10),MONTH(A10),1))
D11: =IF(A11="","",N(B11)+N(C11)) | F11: =IF(A11="","",DATE(YEAR(A11),MONTH(A11),1))
D12: =IF(A12="","",N(B12)+N(C12)) | F12: =IF(A12="","",DATE(YEAR(A12),MONTH(A12),1))
D13: =IF(A13="","",N(B13)+N(C13)) | F13: =IF(A13="","",DATE(YEAR(A13),MONTH(A13),1))
D14: =IF(A14="","",N(B14)+N(C14)) | F14: =IF(A14="","",DATE(YEAR(A14),MONTH(A14),1))
D15: =IF(A15="","",N(B15)+N(C15)) | F15: =IF(A15="","",DATE(YEAR(A15),MONTH(A15),1))
D16: =IF(A16="","",N(B16)+N(C16)) | F16: =IF(A16="","",DATE(YEAR(A16),MONTH(A16),1))
D17: =IF(A17="","",N(B17)+N(C17)) | F17: =IF(A17="","",DATE(YEAR(A17),MONTH(A17),1))
D18: =IF(A18="","",N(B18)+N(C18)) | F18: =IF(A18="","",DATE(YEAR(A18),MONTH(A18),1))
D19: =IF(A19="","",N(B19)+N(C19)) | F19: =IF(A19="","",DATE(YEAR(A19),MONTH(A19),1))
... D200: =IF(A200="","",N(B200)+N(C200)) | F200: =IF(A200="","",DATE(YEAR(A200),MONTH(A200),1))

Sheet CASA
A1: CASA · gastos de la vivienda
A2: Gastos de la vivienda por concepto, últimos 12 meses. Sale de las categorías del grupo «Casa».
A3: Si añades una categoría del grupo «Casa» en CATEGORÍAS, añade aquí su fila.
A4: Concepto | B4: =EDATE(INDEX('MIS DATOS'!$A$6:$A$245,COUNT('MIS DATOS'!$A$6:$A$245)),-11) -> 45931 | C4: =EDATE(INDEX('MIS DATOS'!$A$6:$A$245,COUNT('MIS DATOS'!$A$6:$A$245)),-10) -> 45962 | D4: =EDATE(INDEX('MIS DATOS'!$A$6:$A$245,COUNT('MIS DATOS'!$A$6:$A$245)),-9) -> 45992 | E4: =EDATE(INDEX('MIS DATOS'!$A$6:$A$245,COUNT('MIS DATOS'!$A$6:$A$245)),-8) -> 46023 | F4: =EDATE(INDEX('MIS DATOS'!$A$6:$A$245,COUNT('MIS DATOS'!$A$6:$A$245)),-7) -> 46054 | G4: =EDATE(INDEX('MIS DATOS'!$A$6:$A$245,COUNT('MIS DATOS'!$A$6:$A$245)),-6) -> 46082 | H4: =EDATE(INDEX('MIS DATOS'!$A$6:$A$245,COUNT('MIS DATOS'!$A$6:$A$245)),-5) -> 46113 | I4: =EDATE(INDEX('MIS DATOS'!$A$6:$A$245,COUNT('MIS DATOS'!$A$6:$A$245)),-4) -> 46143 | J4: =EDATE(INDEX('MIS DATOS'!$A$6:$A$245,COUNT('MIS DATOS'!$A$6:$A$245)),-3) -> 46174 | K4: =EDATE(INDEX('MIS DATOS'!$A$6:$A$245,COUNT('MIS DATOS'!$A$6:$A$245)),-2) -> 46204 | L4: =EDATE(INDEX('MIS DATOS'!$A$6:$A$245,COUNT('MIS DATOS'!$A$6:$A$245)),-1) -> 46235 | M4: =EDATE(INDEX('MIS DATOS'!$A$6:$A$245,COUNT('MIS DATOS'!$A$6:$A$245)),0) -> 46266 | N4: Total 12 meses | O4: Media al mes | P4: Último mes
A5: Alquiler | B5: =-SUMIFS(MOVIMIENTOS!$E$4:$E$20000,MOVIMIENTOS!$G$4:$G$20000,$A5,MOVIMIENTOS!$B$4:$B$20000,B$4) -> 850 | C5: =-SUMIFS(MOVIMIENTOS!$E$4:$E$20000,MOVIMIENTOS!$G$4:$G$20000,$A5,MOVIMIENTOS!$B$4:$B$20000,C$4) -> 850 | D5: =-SUMIFS(MOVIMIENTOS!$E$4:$E$20000,MOVIMIENTOS!$G$4:$G$20000,$A5,MOVIMIENTOS!$B$4:$B$20000,D$4) -> 850 | E5: =-SUMIFS(MOVIMIENTOS!$E$4:$E$20000,MOVIMIENTOS!$G$4:$G$20000,$A5,MOVIMIENTOS!$B$4:$B$20000,E$4) -> 850 | F5: =-SUMIFS(MOVIMIENTOS!$E$4:$E$20000,MOVIMIENTOS!$G$4:$G$20000,$A5,MOVIMIENTOS!$B$4:$B$20000,F$4) -> 850 | G5: =-SUMIFS(MOVIMIENTOS!$E$4:$E$20000,MOVIMIENTOS!$G$4:$G$20000,$A5,MOVIMIENTOS!$B$4:$B$20000,G$4) -> 850 | H5: =-SUMIFS(MOVIMIENTOS!$E$4:$E$20000,MOVIMIENTOS!$G$4:$G$20000,$A5,MOVIMIENTOS!$B$4:$B$20000,H$4) -> 850 | I5: =-SUMIFS(MOVIMIENTOS!$E$4:$E$20000,MOVIMIENTOS!$G$4:$G$20000,$A5,MOVIMIENTOS!$B$4:$B$20000,I$4) -> 850 | ... M5: =-SUMIFS(MOVIMIENTOS!$E$4:$E$20000,MOVIMIENTOS!$G$4:$G$20000,$A5,MOVIMIENTOS!$B$4:$B$20000,M$4) -> 850 | N5: =SUM(B5:M5) -> 10200 | O5: =IFERROR(SUMIFS(B5:M5,$B$4:$M$4,"<"&DATE(YEAR(TODAY()),MONTH(TODAY()),1))/$B$15,0) -> 850 | P5: =M5 -> 850
A6: Comunidad | B6: =-SUMIFS(MOVIMIENTOS!$E$4:$E$20000,MOVIMIENTOS!$G$4:$G$20000,$A6,MOVIMIENTOS!$B$4:$B$20000,B$4) -> 0 | C6: =-SUMIFS(MOVIMIENTOS!$E$4:$E$20000,MOVIMIENTOS!$G$4:$G$20000,$A6,MOVIMIENTOS!$B$4:$B$20000,C$4) -> 0 | D6: =-SUMIFS(MOVIMIENTOS!$E$4:$E$20000,MOVIMIENTOS!$G$4:$G$20000,$A6,MOVIMIENTOS!$B$4:$B$20000,D$4) -> 0 | E6: =-SUMIFS(MOVIMIENTOS!$E$4:$E$20000,MOVIMIENTOS!$G$4:$G$20000,$A6,MOVIMIENTOS!$B$4:$B$20000,E$4) -> 0 | F6: =-SUMIFS(MOVIMIENTOS!$E$4:$E$20000,MOVIMIENTOS!$G$4:$G$20000,$A6,MOVIMIENTOS!$B$4:$B$20000,F$4) -> 0 | G6: =-SUMIFS(MOVIMIENTOS!$E$4:$E$20000,MOVIMIENTOS!$G$4:$G$20000,$A6,MOVIMIENTOS!$B$4:$B$20000,G$4) -> 0 | H6: =-SUMIFS(MOVIMIENTOS!$E$4:$E$20000,MOVIMIENTOS!$G$4:$G$20000,$A6,MOVIMIENTOS!$B$4:$B$20000,H$4) -> 0 | I6: =-SUMIFS(MOVIMIENTOS!$E$4:$E$20000,MOVIMIENTOS!$G$4:$G$20000,$A6,MOVIMIENTOS!$B$4:$B$20000,I$4) -> 0 | ... M6: =-SUMIFS(MOVIMIENTOS!$E$4:$E$20000,MOVIMIENTOS!$G$4:$G$20000,$A6,MOVIMIENTOS!$B$4:$B$20000,M$4) -> 0 | N6: =SUM(B6:M6) -> 0 | O6: =IFERROR(SUMIFS(B6:M6,$B$4:$M$4,"<"&DATE(YEAR(TODAY()),MONTH(TODAY()),1))/$B$15,0) -> 0 | P6: =M6 -> 0
A7: Luz y gas | B7: =-SUMIFS(MOVIMIENTOS!$E$4:$E$20000,MOVIMIENTOS!$G$4:$G$20000,$A7,MOVIMIENTOS!$B$4:$B$20000,B$4) -> 37.38 | C7: =-SUMIFS(MOVIMIENTOS!$E$4:$E$20000,MOVIMIENTOS!$G$4:$G$20000,$A7,MOVIMIENTOS!$B$4:$B$20000,C$4) -> 50.32 | D7: =-SUMIFS(MOVIMIENTOS!$E$4:$E$20000,MOVIMIENTOS!$G$4:$G$20000,$A7,MOVIMIENTOS!$B$4:$B$20000,D$4) -> 58.18 | E7: =-SUMIFS(MOVIMIENTOS!$E$4:$E$20000,MOVIMIENTOS!$G$4:$G$20000,$A7,MOVIMIENTOS!$B$4:$B$20000,E$4) -> 63.54 | F7: =-SUMIFS(MOVIMIENTOS!$E$4:$E$20000,MOVIMIENTOS!$G$4:$G$20000,$A7,MOVIMIENTOS!$B$4:$B$20000,F$4) -> 49.8 | G7: =-SUMIFS(MOVIMIENTOS!$E$4:$E$20000,MOVIMIENTOS!$G$4:$G$20000,$A7,MOVIMIENTOS!$B$4:$B$20000,G$4) -> 40.63 | H7: =-SUMIFS(MOVIMIENTOS!$E$4:$E$20000,MOVIMIENTOS!$G$4:$G$20000,$A7,MOVIMIENTOS!$B$4:$B$20000,H$4) -> 36.17 | I7: =-SUMIFS(MOVIMIENTOS!$E$4:$E$20000,MOVIMIENTOS!$G$4:$G$20000,$A7,MOVIMIENTOS!$B$4:$B$20000,I$4) -> 47.6 | ... M7: =-SUMIFS(MOVIMIENTOS!$E$4:$E$20000,MOVIMIENTOS!$G$4:$G$20000,$A7,MOVIMIENTOS!$B$4:$B$20000,M$4) -> 38.08 | N7: =SUM(B7:M7) -> 592.4 | O7: =IFERROR(SUMIFS(B7:M7,$B$4:$M$4,"<"&DATE(YEAR(TODAY()),MONTH(TODAY()),1))/$B$15,0) -> 49.366667 | P7: =M7 -> 38.08
A8: Agua | B8: =-SUMIFS(MOVIMIENTOS!$E$4:$E$20000,MOVIMIENTOS!$G$4:$G$20000,$A8,MOVIMIENTOS!$B$4:$B$20000,B$4) -> 36.52 | C8: =-SUMIFS(MOVIMIENTOS!$E$4:$E$20000,MOVIMIENTOS!$G$4:$G$20000,$A8,MOVIMIENTOS!$B$4:$B$20000,C$4) -> 0 | D8: =-SUMIFS(MOVIMIENTOS!$E$4:$E$20000,MOVIMIENTOS!$G$4:$G$20000,$A8,MOVIMIENTOS!$B$4:$B$20000,D$4) -> 32.13 | E8: =-SUMIFS(MOVIMIENTOS!$E$4:$E$20000,MOVIMIENTOS!$G$4:$G$20000,$A8,MOVIMIENTOS!$B$4:$B$20000,E$4) -> 0 | F8: =-SUMIFS(MOVIMIENTOS!$E$4:$E$20000,MOVIMIENTOS!$G$4:$G$20000,$A8,MOVIMIENTOS!$B$4:$B$20000,F$4) -> 37.59 | G8: =-SUMIFS(MOVIMIENTOS!$E$4:$E$20000,MOVIMIENTOS!$G$4:$G$20000,$A8,MOVIMIENTOS!$B$4:$B$20000,G$4) -> 0 | H8: =-SUMIFS(MOVIMIENTOS!$E$4:$E$20000,MOVIMIENTOS!$G$4:$G$20000,$A8,MOVIMIENTOS!$B$4:$B$20000,H$4) -> 34 | I8: =-SUMIFS(MOVIMIENTOS!$E$4:$E$20000,MOVIMIENTOS!$G$4:$G$20000,$A8,MOVIMIENTOS!$B$4:$B$20000,I$4) -> 0 | ... M8: =-SUMIFS(MOVIMIENTOS!$E$4:$E$20000,MOVIMIENTOS!$G$4:$G$20000,$A8,MOVIMIENTOS!$B$4:$B$20000,M$4) -> 0 | N8: =SUM(B8:M8) -> 213.48 | O8: =IFERROR(SUMIFS(B8:M8,$B$4:$M$4,"<"&DATE(YEAR(TODAY()),MONTH(TODAY()),1))/$B$15,0) -> 17.79 | P8: =M8 -> 0
A9: Internet y teléfono fijo | B9: =-SUMIFS(MOVIMIENTOS!$E$4:$E$20000,MOVIMIENTOS!$G$4:$G$20000,$A9,MOVIMIENTOS!$B$4:$B$20000,B$4) -> 39.9 | C9: =-SUMIFS(MOVIMIENTOS!$E$4:$E$20000,MOVIMIENTOS!$G$4:$G$20000,$A9,MOVIMIENTOS!$B$4:$B$20000,C$4) -> 39.9 | D9: =-SUMIFS(MOVIMIENTOS!$E$4:$E$20000,MOVIMIENTOS!$G$4:$G$20000,$A9,MOVIMIENTOS!$B$4:$B$20000,D$4) -> 39.9 | E9: =-SUMIFS(MOVIMIENTOS!$E$4:$E$20000,MOVIMIENTOS!$G$4:$G$20000,$A9,MOVIMIENTOS!$B$4:$B$20000,E$4) -> 39.9 | F9: =-SUMIFS(MOVIMIENTOS!$E$4:$E$20000,MOVIMIENTOS!$G$4:$G$20000,$A9,MOVIMIENTOS!$B$4:$B$20000,F$4) -> 39.9 | G9: =-SUMIFS(MOVIMIENTOS!$E$4:$E$20000,MOVIMIENTOS!$G$4:$G$20000,$A9,MOVIMIENTOS!$B$4:$B$20000,G$4) -> 39.9 | H9: =-SUMIFS(MOVIMIENTOS!$E$4:$E$20000,MOVIMIENTOS!$G$4:$G$20000,$A9,MOVIMIENTOS!$B$4:$B$20000,H$4) -> 39.9 | I9: =-SUMIFS(MOVIMIENTOS!$E$4:$E$20000,MOVIMIENTOS!$G$4:$G$20000,$A9,MOVIMIENTOS!$B$4:$B$20000,I$4) -> 39.9 | ... M9: =-SUMIFS(MOVIMIENTOS!$E$4:$E$20000,MOVIMIENTOS!$G$4:$G$20000,$A9,MOVIMIENTOS!$B$4:$B$20000,M$4) -> 39.9 | N9: =SUM(B9:M9) -> 478.8 | O9: =IFERROR(SUMIFS(B9:M9,$B$4:$M$4,"<"&DATE(YEAR(TODAY()),MONTH(TODAY()),1))/$B$15,0) -> 39.9 | P9: =M9 -> 39.9
A10: IBI y tasas | B10: =-SUMIFS(MOVIMIENTOS!$E$4:$E$20000,MOVIMIENTOS!$G$4:$G$20000,$A10,MOVIMIENTOS!$B$4:$B$20000,B$4) -> 0 | C10: =-SUMIFS(MOVIMIENTOS!$E$4:$E$20000,MOVIMIENTOS!$G$4:$G$20000,$A10,MOVIMIENTOS!$B$4:$B$20000,C$4) -> 0 | D10: =-SUMIFS(MOVIMIENTOS!$E$4:$E$20000,MOVIMIENTOS!$G$4:$G$20000,$A10,MOVIMIENTOS!$B$4:$B$20000,D$4) -> 0 | E10: =-SUMIFS(MOVIMIENTOS!$E$4:$E$20000,MOVIMIENTOS!$G$4:$G$20000,$A10,MOVIMIENTOS!$B$4:$B$20000,E$4) -> 0 | F10: =-SUMIFS(MOVIMIENTOS!$E$4:$E$20000,MOVIMIENTOS!$G$4:$G$20000,$A10,MOVIMIENTOS!$B$4:$B$20000,F$4) -> 0 | G10: =-SUMIFS(MOVIMIENTOS!$E$4:$E$20000,MOVIMIENTOS!$G$4:$G$20000,$A10,MOVIMIENTOS!$B$4:$B$20000,G$4) -> 0 | H10: =-SUMIFS(MOVIMIENTOS!$E$4:$E$20000,MOVIMIENTOS!$G$4:$G$20000,$A10,MOVIMIENTOS!$B$4:$B$20000,H$4) -> 0 | I10: =-SUMIFS(MOVIMIENTOS!$E$4:$E$20000,MOVIMIENTOS!$G$4:$G$20000,$A10,MOVIMIENTOS!$B$4:$B$20000,I$4) -> 0 | ... M10: =-SUMIFS(MOVIMIENTOS!$E$4:$E$20000,MOVIMIENTOS!$G$4:$G$20000,$A10,MOVIMIENTOS!$B$4:$B$20000,M$4) -> 0 | N10: =SUM(B10:M10) -> 0 | O10: =IFERROR(SUMIFS(B10:M10,$B$4:$M$4,"<"&DATE(YEAR(TODAY()),MONTH(TODAY()),1))/$B$15,0) -> 0 | P10: =M10 -> 0
